Workbook

Sheet MIS FINANZAS
B3: Salario mensual objetivo | C3: 500000
B5: INGRESOS | H5: GASTOS
B6: Fuente de ingreso | C6: Fijo/Variable | D6: ¿Cada cuanto? | E6: Categoría | F6: Valor | H6: Concepto de gasto | I6: Tipo | J6: ¿Cada cuanto? | K6: Categoría | L6: Valor | AS6: =LOOKUP(1000000,AQ:AQ) -> 6
B7: Salario | C7: Fijo | D7: Mensual | E7: Salario | F7: 4000000 | H7: Arriendo | I7: Necesario | J7: Mensual | K7: Hogar | L7: 1700000 | AQ7: =IF(AR7<>0,AQ6+1,"") -> 1 | AR7: =B7 -> Salario | AS7: =IF(AT7<>0,AS6+1,"") -> 7 | AT7: =H7 -> Arriendo | AU7: =C7 -> Fijo | AV7: =E7 -> Salario | AW7: =IF(D7="Mensual",F7,IF(D7="Bimensual",F7/2,IF(D7="Trimestral",F7/3,IF(D7="Semestral",F7/6,IF(D7="Anual",F7/12,""))))) -> 4000000 | AX7: =I7 -> Necesario | AY7: =K7 -> Hogar | AZ7: =IF(J7="Mensual",L7,IF(J7="Bimensual",L7/2,IF(J7="Trimestral",L7/3,IF(J7="Semestral",L7/6,IF(J7="Anual",L7/12,""))))) -> 1700000
B8: Prima salario | C8: Fijo | D8: Semestral | E8: Otros ingresos | F8: 2000000 | H8: Administración | I8: Necesario | J8: Mensual | K8: Hogar | L8: 150000 | AQ8: =IF(AR8<>0,AQ7+1,"") -> 2 | AR8: =B8 -> Prima salario | AS8: =IF(AT8<>0,AS7+1,"") -> 8 | AT8: =H8 -> Administración | AU8: =C8 -> Fijo | AV8: =E8 -> Otros ingresos | AW8: =IF(D8="Mensual",F8,IF(D8="Bimensual",F8/2,IF(D8="Trimestral",F8/3,IF(D8="Semestral",F8/6,IF(D8="Anual",F8/12,""))))) -> 333333.33 | AX8: =I8 -> Necesario | AY8: =K8 -> Hogar | AZ8: =IF(J8="Mensual",L8,IF(J8="Bimensual",L8/2,IF(J8="Trimestral",L8/3,IF(J8="Semestral",L8/6,IF(J8="Anual",L8/12,""))))) -> 150000
B9: Proyectos asesorias | C9: Variable | D9: Trimestral | E9: Negocio | F9: 3500000 | H9: Mercado | I9: Necesario | J9: Mensual | K9: Alimentación | L9: 500000 | AQ9: =IF(AR9<>0,AQ8+1,"") -> 3 | AR9: =B9 -> Proyectos asesorias | AS9: =IF(AT9<>0,AS8+1,"") -> 9 | AT9: =H9 -> Mercado | AU9: =C9 -> Variable | AV9: =E9 -> Negocio | AW9: =IF(D9="Mensual",F9,IF(D9="Bimensual",F9/2,IF(D9="Trimestral",F9/3,IF(D9="Semestral",F9/6,IF(D9="Anual",F9/12,""))))) -> 1166666.7 | AX9: =I9 -> Necesario | AY9: =K9 -> Alimentación | AZ9: =IF(J9="Mensual",L9,IF(J9="Bimensual",L9/2,IF(J9="Trimestral",L9/3,IF(J9="Semestral",L9/6,IF(J9="Anual",L9/12,""))))) -> 500000
B10: Dividendos inversiones | C10: Variable | D10: Anual | E10: Inversión | F10: 2000000 | H10: Agua | I10: Necesario | J10: Bimensual | K10: Hogar | L10: 150000 | AQ10: =IF(AR10<>0,AQ9+1,"") -> 4 | AR10: =B10 -> Dividendos inversiones | AS10: =IF(AT10<>0,AS9+1,"") -> 10 | AT10: =H10 -> Agua | AU10: =C10 -> Variable | AV10: =E10 -> Inversión | AW10: =IF(D10="Mensual",F10,IF(D10="Bimensual",F10/2,IF(D10="Trimestral",F10/3,IF(D10="Semestral",F10/6,IF(D10="Anual",F10/12,""))))) -> 166666.67 | AX10: =I10 -> Necesario | AY10: =K10 -> Hogar | AZ10: =IF(J10="Mensual",L10,IF(J10="Bimensual",L10/2,IF(J10="Trimestral",L10/3,IF(J10="Semestral",L10/6,IF(J10="Anual",L10/12,""))))) -> 75000
B11: Bonos adicionales | C11: Variable | D11: Trimestral | E11: Otros ingresos | F11: 2500000 | H11: Luz | I11: Necesario | J11: Mensual | K11: Hogar | L11: 120000 | AQ11: =IF(AR11<>0,AQ10+1,"") -> 5 | AR11: =B11 -> Bonos adicionales | AS11: =IF(AT11<>0,AS10+1,"") -> 11 | AT11: =H11 -> Luz | AU11: =C11 -> Variable | AV11: =E11 -> Otros ingresos | AW11: =IF(D11="Mensual",F11,IF(D11="Bimensual",F11/2,IF(D11="Trimestral",F11/3,IF(D11="Semestral",F11/6,IF(D11="Anual",F11/12,""))))) -> 833333.33 | AX11: =I11 -> Necesario | AY11: =K11 -> Hogar | AZ11: =IF(J11="Mensual",L11,IF(J11="Bimensual",L11/2,IF(J11="Trimestral",L11/3,IF(J11="Semestral",L11/6,IF(J11="Anual",L11/12,""))))) -> 120000
B12: Otro | C12: Variable | D12: Mensual | E12: Otros ingresos | F12: 700000 | H12: Gas | I12: Necesario | J12: Mensual | K12: Hogar | L12: 40000 | AQ12: =IF(AR12<>0,AQ11+1,"") -> 6 | AR12: =B12 -> Otro | AS12: =IF(AT12<>0,AS11+1,"") -> 12 | AT12: =H12 -> Gas | AU12: =C12 -> Variable | AV12: =E12 -> Otros ingresos | AW12: =IF(D12="Mensual",F12,IF(D12="Bimensual",F12/2,IF(D12="Trimestral",F12/3,IF(D12="Semestral",F12/6,IF(D12="Anual",F12/12,""))))) -> 700000 | AX12: =I12 -> Necesario | AY12: =K12 -> Hogar | AZ12: =IF(J12="Mensual",L12,IF(J12="Bimensual",L12/2,IF(J12="Trimestral",L12/3,IF(J12="Semestral",L12/6,IF(J12="Anual",L12/12,""))))) -> 40000
H13: Provisiones pagos | I13: Necesario | J13: Mensual | K13: Provisiones | L13: 200000 | AQ13: =IF(AR13<>0,AQ12+1,"") | AR13: =B13 | AS13: =IF(AT13<>0,AS12+1,"") -> 13 | AT13: =H13 -> Provisiones pagos | AU13: =C13 | AV13: =E13 | AW13: =IF(D13="Mensual",F13,IF(D13="Bimensual",F13/2,IF(D13="Trimestral",F13/3,IF(D13="Semestral",F13/6,IF(D13="Anual",F13/12,""))))) | AX13: =I13 -> Necesario | AY13: =K13 -> Provisiones | AZ13: =IF(J13="Mensual",L13,IF(J13="Bimensual",L13/2,IF(J13="Trimestral",L13/3,IF(J13="Semestral",L13/6,IF(J13="Anual",L13/12,""))))) -> 200000
H14: Plan de datos | I14: No tan necesario | J14: Mensual | K14: Otros gastos | L14: 80000 | AQ14: =IF(AR14<>0,AQ13+1,"") | AR14: =B14 | AS14: =IF(AT14<>0,AS13+1,"") -> 14 | AT14: =H14 -> Plan de datos | AU14: =C14 | AV14: =E14 | AW14: =IF(D14="Mensual",F14,IF(D14="Bimensual",F14/2,IF(D14="Trimestral",F14/3,IF(D14="Semestral",F14/6,IF(D14="Anual",F14/12,""))))) | AX14: =I14 -> No tan necesario | AY14: =K14 -> Otros gastos | AZ14: =IF(J14="Mensual",L14,IF(J14="Bimensual",L14/2,IF(J14="Trimestral",L14/3,IF(J14="Semestral",L14/6,IF(J14="Anual",L14/12,""))))) -> 80000
H15: Gasolina | I15: Necesario | J15: Mensual | K15: Transporte | L15: 150000 | AQ15: =IF(AR15<>0,AQ14+1,"") | AR15: =B15 | AS15: =IF(AT15<>0,AS14+1,"") -> 15 | AT15: =H15 -> Gasolina | AU15: =C15 | AV15: =E15 | AW15: =IF(D15="Mensual",F15,IF(D15="Bimensual",F15/2,IF(D15="Trimestral",F15/3,IF(D15="Semestral",F15/6,IF(D15="Anual",F15/12,""))))) | AX15: =I15 -> Necesario | AY15: =K15 -> Transporte | AZ15: =IF(J15="Mensual",L15,IF(J15="Bimensual",L15/2,IF(J15="Trimestral",L15/3,IF(J15="Semestral",L15/6,IF(J15="Anual",L15/12,""))))) -> 150000
H16: Mantenimiento carro | I16: Necesario | J16: Trimestral | K16: Transporte | L16: 500000 | AQ16: =IF(AR16<>0,AQ15+1,"") | AR16: =B16 | AS16: =IF(AT16<>0,AS15+1,"") -> 16 | AT16: =H16 -> Mantenimiento carro | AU16: =C16 | AV16: =E16 | AW16: =IF(D16="Mensual",F16,IF(D16="Bimensual",F16/2,IF(D16="Trimestral",F16/3,IF(D16="Semestral",F16/6,IF(D16="Anual",F16/12,""))))) | AX16: =I16 -> Necesario | AY16: =K16 -> Transporte | AZ16: =IF(J16="Mensual",L16,IF(J16="Bimensual",L16/2,IF(J16="Trimestral",L16/3,IF(J16="Semestral",L16/6,IF(J16="Anual",L16/12,""))))) -> 166666.67
H17: Seguro carro | I17: No tan necesario | J17: Anual | K17: Transporte | L17: 1000000 | AQ17: =IF(AR17<>0,AQ16+1,"") | AR17: =B17 | AS17: =IF(AT17<>0,AS16+1,"") -> 17 | AT17: =H17 -> Seguro carro | AU17: =C17 | AV17: =E17 | AW17: =IF(D17="Mensual",F17,IF(D17="Bimensual",F17/2,IF(D17="Trimestral",F17/3,IF(D17="Semestral",F17/6,IF(D17="Anual",F17/12,""))))) | AX17: =I17 -> No tan necesario | AY17: =K17 -> Transporte | AZ17: =IF(J17="Mensual",L17,IF(J17="Bimensual",L17/2,IF(J17="Trimestral",L17/3,IF(J17="Semestral",L17/6,IF(J17="Anual",L17/12,""))))) -> 83333.333
H18: Gimnasio | I18: No tan necesario | J18: Anual | K18: Otros gastos | L18: 900000 | AQ18: =IF(AR18<>0,AQ17+1,"") | AR18: =B18 | AS18: =IF(AT18<>0,AS17+1,"") -> 18 | AT18: =H18 -> Gimnasio | AU18: =C18 | AV18: =E18 | AW18: =IF(D18="Mensual",F18,IF(D18="Bimensual",F18/2,IF(D18="Trimestral",F18/3,IF(D18="Semestral",F18/6,IF(D18="Anual",F18/12,""))))) | AX18: =I18 -> No tan necesario | AY18: =K18 -> Otros gastos | AZ18: =IF(J18="Mensual",L18,IF(J18="Bimensual",L18/2,IF(J18="Trimestral",L18/3,IF(J18="Semestral",L18/6,IF(J18="Anual",L18/12,""))))) -> 75000
H19: Internet y telefono | I19: No necesario | J19: Mensual | K19: Familia | L19: 120000 | AQ19: =IF(AR19<>0,AQ18+1,"") | AR19: =B19 | AS19: =IF(AT19<>0,AS18+1,"") -> 19 | AT19: =H19 -> Internet y telefono | AU19: =C19 | AV19: =E19 | AW19: =IF(D19="Mensual",F19,IF(D19="Bimensual",F19/2,IF(D19="Trimestral",F19/3,IF(D19="Semestral",F19/6,IF(D19="Anual",F19/12,""))))) | AX19: =I19 -> No necesario | AY19: =K19 -> Familia | AZ19: =IF(J19="Mensual",L19,IF(J19="Bimensual",L19/2,IF(J19="Trimestral",L19/3,IF(J19="Semestral",L19/6,IF(J19="Anual",L19/12,""))))) -> 120000
H20: Streaming (Netflix, spotify…) | I20: No tan necesario | J20: Mensual | K20: Familia | L20: 120000 | AQ20: =IF(AR20<>0,AQ19+1,"") | AR20: =B20 | AS20: =IF(AT20<>0,AS19+1,"") -> 20 | AT20: =H20 -> Streaming (Netflix, spotify…) | AU20: =C20 | AV20: =E20 | AW20: =IF(D20="Mensual",F20,IF(D20="Bimensual",F20/2,IF(D20="Trimestral",F20/3,IF(D20="Semestral",F20/6,IF(D20="Anual",F20/12,""))))) | AX20: =I20 -> No tan necesario | AY20: =K20 -> Familia | AZ20: =IF(J20="Mensual",L20,IF(J20="Bimensual",L20/2,IF(J20="Trimestral",L20/3,IF(J20="Semestral",L20/6,IF(J20="Anual",L20/12,""))))) -> 120000
H21: Taxi/Uber/Bus | I21: No tan necesario | J21: Mensual | K21: Transporte | L21: 140000 | AQ21: =IF(AR21<>0,AQ20+1,"") | AR21: =B21 | AS21: =IF(AT21<>0,AS20+1,"") -> 21 | AT21: =H21 -> Taxi/Uber/Bus | AU21: =C21 | AV21: =E21 | AW21: =IF(D21="Mensual",F21,IF(D21="Bimensual",F21/2,IF(D21="Trimestral",F21/3,IF(D21="Semestral",F21/6,IF(D21="Anual",F21/12,""))))) | AX21: =I21 -> No tan necesario | AY21: =K21 -> Transporte | AZ21: =IF(J21="Mensual",L21,IF(J21="Bimensual",L21/2,IF(J21="Trimestral",L21/3,IF(J21="Semestral",L21/6,IF(J21="Anual",L21/12,""))))) -> 140000
H22: Crédito carro | I22: Necesario | J22: Mensual | K22: Deudas entidades | L22: 1200000 | AQ22: =IF(AR22<>0,AQ21+1,"") | AR22: =B22 | AS22: =IF(AT22<>0,AS21+1,"") -> 22 | AT22: =H22 -> Crédito carro | AU22: =C22 | AV22: =E22 | AW22: =IF(D22="Mensual",F22,IF(D22="Bimensual",F22/2,IF(D22="Trimestral",F22/3,IF(D22="Semestral",F22/6,IF(D22="Anual",F22/12,""))))) | AX22: =I22 -> Necesario | AY22: =K22 -> Deudas entidades | AZ22: =IF(J22="Mensual",L22,IF(J22="Bimensual",L22/2,IF(J22="Trimestral",L22/3,IF(J22="Semestral",L22/6,IF(J22="Anual",L22/12,""))))) -> 1200000
H23: Viajes | I23: No tan necesario | J23: Semestral | K23: Entretenimiento | L23: 4000000 | AQ23: =IF(AR23<>0,AQ22+1,"") | AR23: =B23 | AS23: =IF(AT23<>0,AS22+1,"") -> 23 | AT23: =H23 -> Viajes | AU23: =C23 | AV23: =E23 | AW23: =IF(D23="Mensual",F23,IF(D23="Bimensual",F23/2,IF(D23="Trimestral",F23/3,IF(D23="Semestral",F23/6,IF(D23="Anual",F23/12,""))))) | AX23: =I23 -> No tan necesario | AY23: =K23 -> Entretenimiento | AZ23: =IF(J23="Mensual",L23,IF(J23="Bimensual",L23/2,IF(J23="Trimestral",L23/3,IF(J23="Semestral",L23/6,IF(J23="Anual",L23/12,""))))) -> 666666.67
H24: Restaurantes | I24: No necesario | J24: Mensual | K24: Entretenimiento | L24: 600000 | AQ24: =IF(AR24<>0,AQ23+1,"") | AR24: =B24 | AS24: =IF(AT24<>0,AS23+1,"") -> 24 | AT24: =H24 -> Restaurantes | AU24: =C24 | AV24: =E24 | AW24: =IF(D24="Mensual",F24,IF(D24="Bimensual",F24/2,IF(D24="Trimestral",F24/3,IF(D24="Semestral",F24/6,IF(D24="Anual",F24/12,""))))) | AX24: =I24 -> No necesario | AY24: =K24 -> Entretenimiento | AZ24: =IF(J24="Mensual",L24,IF(J24="Bimensual",L24/2,IF(J24="Trimestral",L24/3,IF(J24="Semestral",L24/6,IF(J24="Anual",L24/12,""))))) -> 600000
... H32: Ropa | I32: No tan necesario | J32: Trimestral | K32: Otros gastos | L32: 1500000 | AQ32: =IF(AR32<>0,AQ31+1,"") | AR32: =B32 | AS32: =IF(AT32<>0,AS31+1,"") -> 32 | AT32: =H32 -> Ropa | AU32: =C32 | AV32: =E32 | AW32: =IF(D32="Mensual",F32,IF(D32="Bimensual",F32/2,IF(D32="Trimestral",F32/3,IF(D32="Semestral",F32/6,IF(D32="Anual",F32/12,""))))) | AX32: =I32 -> No tan necesario | AY32: =K32 -> Otros gastos | AZ32: =IF(J32="Mensual",L32,IF(J32="Bimensual",L32/2,IF(J32="Trimestral",L32/3,IF(J32="Semestral",L32/6,IF(J32="Anual",L32/12,""))))) -> 500000
AQ33: =IF(AR33<>0,AQ32+1,"") | AR33: =B33 | AS33: =IF(AT33<>0,AS32+1,"") | AT33: =H33 | AU33: =C33 | AV33: =E33 | AW33: =IF(D33="Mensual",F33,IF(D33="Bimensual",F33/2,IF(D33="Trimestral",F33/3,IF(D33="Semestral",F33/6,IF(D33="Anual",F33/12,""))))) | AX33: =I33 | AY33: =K33 | AZ33: =IF(J33="Mensual",L33,IF(J33="Bimensual",L33/2,IF(J33="Trimestral",L33/3,IF(J33="Semestral",L33/6,IF(J33="Anual",L33/12,"")))))
AQ34: =IF(AR34<>0,AQ33+1,"") | AR34: =B34 | AS34: =IF(AT34<>0,AS33+1,"") | AT34: =H34 | AU34: =C34 | AV34: =E34 | AW34: =IF(D34="Mensual",F34,IF(D34="Bimensual",F34/2,IF(D34="Trimestral",F34/3,IF(D34="Semestral",F34/6,IF(D34="Anual",F34/12,""))))) | AX34: =I34 | AY34: =K34 | AZ34: =IF(J34="Mensual",L34,IF(J34="Bimensual",L34/2,IF(J34="Trimestral",L34/3,IF(J34="Semestral",L34/6,IF(J34="Anual",L34/12,"")))))
AQ35: =IF(AR35<>0,AQ34+1,"") | AR35: =B35 | AS35: =IF(AT35<>0,AS34+1,"") | AT35: =H35 | AU35: =C35 | AV35: =E35 | AW35: =IF(D35="Mensual",F35,IF(D35="Bimensual",F35/2,IF(D35="Trimestral",F35/3,IF(D35="Semestral",F35/6,IF(D35="Anual",F35/12,""))))) | AX35: =I35 | AY35: =K35 | AZ35: =IF(J35="Mensual",L35,IF(J35="Bimensual",L35/2,IF(J35="Trimestral",L35/3,IF(J35="Semestral",L35/6,IF(J35="Anual",L35/12,"")))))
AQ36: =IF(AR36<>0,AQ35+1,"") | AR36: =B36 | AS36: =IF(AT36<>0,AS35+1,"") | AT36: =H36 | AU36: =C36 | AV36: =E36 | AW36: =IF(D36="Mensual",F36,IF(D36="Bimensual",F36/2,IF(D36="Trimestral",F36/3,IF(D36="Semestral",F36/6,IF(D36="Anual",F36/12,""))))) | AX36: =I36 | AY36: =K36 | AZ36: =IF(J36="Mensual",L36,IF(J36="Bimensual",L36/2,IF(J36="Trimestral",L36/3,IF(J36="Semestral",L36/6,IF(J36="Anual",L36/12,"")))))
AQ37: =IF(AR37<>0,AQ36+1,"") | AR37: =B37 | AS37: =IF(AT37<>0,AS36+1,"") | AT37: =H37 | AU37: =C37 | AV37: =E37 | AW37: =IF(D37="Mensual",F37,IF(D37="Bimensual",F37/2,IF(D37="Trimestral",F37/3,IF(D37="Semestral",F37/6,IF(D37="Anual",F37/12,""))))) | AX37: =I37 | AY37: =K37 | AZ37: =IF(J37="Mensual",L37,IF(J37="Bimensual",L37/2,IF(J37="Trimestral",L37/3,IF(J37="Semestral",L37/6,IF(J37="Anual",L37/12,"")))))
AQ38: =IF(AR38<>0,AQ37+1,"") | AR38: =B38 | AS38: =IF(AT38<>0,AS37+1,"") | AT38: =H38 | AU38: =C38 | AV38: =E38 | AW38: =IF(D38="Mensual",F38,IF(D38="Bimensual",F38/2,IF(D38="Trimestral",F38/3,IF(D38="Semestral",F38/6,IF(D38="Anual",F38/12,""))))) | AX38: =I38 | AY38: =K38 | AZ38: =IF(J38="Mensual",L38,IF(J38="Bimensual",L38/2,IF(J38="Trimestral",L38/3,IF(J38="Semestral",L38/6,IF(J38="Anual",L38/12,"")))))
AQ39: =IF(AR39<>0,AQ38+1,"") | AR39: =B39 | AS39: =IF(AT39<>0,AS38+1,"") | AT39: =H39 | AU39: =C39 | AV39: =E39 | AW39: =IF(D39="Mensual",F39,IF(D39="Bimensual",F39/2,IF(D39="Trimestral",F39/3,IF(D39="Semestral",F39/6,IF(D39="Anual",F39/12,""))))) | AX39: =I39 | AY39: =K39 | AZ39: =IF(J39="Mensual",L39,IF(J39="Bimensual",L39/2,IF(J39="Trimestral",L39/3,IF(J39="Semestral",L39/6,IF(J39="Anual",L39/12,"")))))
AQ40: =IF(AR40<>0,AQ39+1,"") | AR40: =B40 | AS40: =IF(AT40<>0,AS39+1,"") | AT40: =H40 | AU40: =C40 | AV40: =E40 | AW40: =IF(D40="Mensual",F40,IF(D40="Bimensual",F40/2,IF(D40="Trimestral",F40/3,IF(D40="Semestral",F40/6,IF(D40="Anual",F40/12,""))))) | AX40: =I40 | AY40: =K40 | AZ40: =IF(J40="Mensual",L40,IF(J40="Bimensual",L40/2,IF(J40="Trimestral",L40/3,IF(J40="Semestral",L40/6,IF(J40="Anual",L40/12,"")))))
AQ41: =IF(AR41<>0,AQ40+1,"") | AR41: =B41 | AS41: =IF(AT41<>0,AS40+1,"") | AT41: =H41 | AU41: =C41 | AV41: =E41 | AW41: =IF(D41="Mensual",F41,IF(D41="Bimensual",F41/2,IF(D41="Trimestral",F41/3,IF(D41="Semestral",F41/6,IF(D41="Anual",F41/12,""))))) | AX41: =I41 | AY41: =K41 | AZ41: =IF(J41="Mensual",L41,IF(J41="Bimensual",L41/2,IF(J41="Trimestral",L41/3,IF(J41="Semestral",L41/6,IF(J41="Anual",L41/12,"")))))
AQ42: =IF(AR42<>0,AQ41+1,"") | AR42: =B42 | AS42: =IF(AT42<>0,AS41+1,"") | AT42: =H42 | AU42: =C42 | AV42: =E42 | AW42: =IF(D42="Mensual",F42,IF(D42="Bimensual",F42/2,IF(D42="Trimestral",F42/3,IF(D42="Semestral",F42/6,IF(D42="Anual",F42/12,""))))) | AX42: =I42 | AY42: =K42 | AZ42: =IF(J42="Mensual",L42,IF(J42="Bimensual",L42/2,IF(J42="Trimestral",L42/3,IF(J42="Semestral",L42/6,IF(J42="Anual",L42/12,"")))))
AQ43: =IF(AR43<>0,AQ42+1,"") | AR43: =B43 | AS43: =IF(AT43<>0,AS42+1,"") | AT43: =H43 | AU43: =C43 | AV43: =E43 | AW43: =IF(D43="Mensual",F43,IF(D43="Bimensual",F43/2,IF(D43="Trimestral",F43/3,IF(D43="Semestral",F43/6,IF(D43="Anual",F43/12,""))))) | AX43: =I43 | AY43: =K43 | AZ43: =IF(J43="Mensual",L43,IF(J43="Bimensual",L43/2,IF(J43="Trimestral",L43/3,IF(J43="Semestral",L43/6,IF(J43="Anual",L43/12,"")))))
AQ44: =IF(AR44<>0,AQ43+1,"") | AR44: =B44 | AS44: =IF(AT44<>0,AS43+1,"") | AT44: =H44 | AU44: =C44 | AV44: =E44 | AW44: =IF(D44="Mensual",F44,IF(D44="Bimensual",F44/2,IF(D44="Trimestral",F44/3,IF(D44="Semestral",F44/6,IF(D44="Anual",F44/12,""))))) | AX44: =I44 | AY44: =K44 | AZ44: =IF(J44="Mensual",L44,IF(J44="Bimensual",L44/2,IF(J44="Trimestral",L44/3,IF(J44="Semestral",L44/6,IF(J44="Anual",L44/12,"")))))
... AQ103: =IF(AR103<>0,AQ102+1,"") | AR103: =B103 | AS103: =IF(AT103<>0,AS102+1,"") | AT103: =H103 | AU103: =C103 | AV103: =E103 | AW103: =IF(D103="Mensual",F103,IF(D103="Bimensual",F103/2,IF(D103="Trimestral",F103/3,IF(D103="Semestral",F103/6,IF(D103="Anual",F103/12,""))))) | AX103: =I103 | AY103: =K103 | AZ103: =IF(J103="Mensual",L103,IF(J103="Bimensual",L103/2,IF(J103="Trimestral",L103/3,IF(J103="Semestral",L103/6,IF(J103="Anual",L103/12,"")))))

Sheet PRESUPUESTO
C6: MENSUAL | G6: ANUAL
B7: INGRESOS | C7: Fijo | D7: Variable | F7: Total | G7: Fijo | H7: Variable | J7: Total
B8: Salario | C8: =SUMIFS('MIS FINANZAS'!$AW$7:$AW$103,'MIS FINANZAS'!$C$7:$C$103,$C$7,'MIS FINANZAS'!$E$7:$E$103,B8) -> 4000000 | D8: =SUMIFS('MIS FINANZAS'!$AW$7:$AW$103,'MIS FINANZAS'!$C$7:$C$103,$D$7,'MIS FINANZAS'!$E$7:$E$103,B8) -> 0 | F8: =C8+D8 -> 4000000 | G8: =C8*12 -> 48000000 | H8: =D8*12 -> 0 | J8: =F8*12 -> 48000000
B9: Negocio | C9: =SUMIFS('MIS FINANZAS'!$AW$7:$AW$103,'MIS FINANZAS'!$C$7:$C$103,$C$7,'MIS FINANZAS'!$E$7:$E$103,B9) -> 0 | D9: =SUMIFS('MIS FINANZAS'!$AW$7:$AW$103,'MIS FINANZAS'!$C$7:$C$103,$D$7,'MIS FINANZAS'!$E$7:$E$103,B9) -> 1166666.7 | F9: =C9+D9 -> 1166666.7 | G9: =C9*12 -> 0 | H9: =D9*12 -> 14000000 | J9: =F9*12 -> 14000000
B10: Inversión | C10: =SUMIFS('MIS FINANZAS'!$AW$7:$AW$103,'MIS FINANZAS'!$C$7:$C$103,$C$7,'MIS FINANZAS'!$E$7:$E$103,B10) -> 0 | D10: =SUMIFS('MIS FINANZAS'!$AW$7:$AW$103,'MIS FINANZAS'!$C$7:$C$103,$D$7,'MIS FINANZAS'!$E$7:$E$103,B10) -> 166666.67 | F10: =C10+D10 -> 166666.67 | G10: =C10*12 -> 0 | H10: =D10*12 -> 2000000 | J10: =F10*12 -> 2000000
B11: Otros ingresos | C11: =SUMIFS('MIS FINANZAS'!$AW$7:$AW$103,'MIS FINANZAS'!$C$7:$C$103,$C$7,'MIS FINANZAS'!$E$7:$E$103,B11) -> 333333.33 | D11: =SUMIFS('MIS FINANZAS'!$AW$7:$AW$103,'MIS FINANZAS'!$C$7:$C$103,$D$7,'MIS FINANZAS'!$E$7:$E$103,B11) -> 1533333.3 | F11: =C11+D11 -> 1866666.7 | G11: =C11*12 -> 4000000 | H11: =D11*12 -> 18400000 | J11: =F11*12 -> 22400000
B12: TOTAL INGRESOS | C12: =SUM(C8:C11) -> 4333333.3 | D12: =SUM(D8:D11) -> 2866666.7 | F12: =SUM(F8:F11) -> 7200000 | G12: =SUM(G8:G11) -> 52000000 | H12: =SUM(H8:H11) -> 34400000 | J12: =SUM(J8:J11) -> 86400000
B13: GASTOS | C13: Necesario | D13: No tan necesario | E13: No necesario | F13: Total | G13: Necesario | H13: No tan necesario | I13: No necesario | J13: Total
B14: Hogar | C14: =SUMIFS('MIS FINANZAS'!$AZ:$AZ,'MIS FINANZAS'!AX:AX,PRESUPUESTO!$C$13,'MIS FINANZAS'!AY:AY,PRESUPUESTO!B14) -> 2085000 | D14: =SUMIFS('MIS FINANZAS'!$AZ:$AZ,'MIS FINANZAS'!AX:AX,PRESUPUESTO!$D$13,'MIS FINANZAS'!AY:AY,PRESUPUESTO!B14) -> 0 | E14: =SUMIFS('MIS FINANZAS'!$AZ:$AZ,'MIS FINANZAS'!AX:AX,PRESUPUESTO!$E$13,'MIS FINANZAS'!AY:AY,PRESUPUESTO!B14) -> 0 | F14: =C14+D14+E14 -> 2085000 | G14: =C14*12 -> 25020000 | H14: =D14*12 -> 0 | I14: =E14*12 -> 0 | J14: =F14*12 -> 25020000
B15: Alimentación | C15: =SUMIFS('MIS FINANZAS'!$AZ:$AZ,'MIS FINANZAS'!AX:AX,PRESUPUESTO!$C$13,'MIS FINANZAS'!AY:AY,PRESUPUESTO!B15) -> 500000 | D15: =SUMIFS('MIS FINANZAS'!$AZ:$AZ,'MIS FINANZAS'!AX:AX,PRESUPUESTO!$D$13,'MIS FINANZAS'!AY:AY,PRESUPUESTO!B15) -> 0 | E15: =SUMIFS('MIS FINANZAS'!$AZ:$AZ,'MIS FINANZAS'!AX:AX,PRESUPUESTO!$E$13,'MIS FINANZAS'!AY:AY,PRESUPUESTO!B15) -> 400000 | F15: =C15+D15+E15 -> 900000 | G15: =C15*12 -> 6000000 | H15: =D15*12 -> 0 | I15: =E15*12 -> 4800000 | J15: =F15*12 -> 10800000
B16: Transporte | C16: =SUMIFS('MIS FINANZAS'!$AZ:$AZ,'MIS FINANZAS'!AX:AX,PRESUPUESTO!$C$13,'MIS FINANZAS'!AY:AY,PRESUPUESTO!B16) -> 316666.67 | D16: =SUMIFS('MIS FINANZAS'!$AZ:$AZ,'MIS FINANZAS'!AX:AX,PRESUPUESTO!$D$13,'MIS FINANZAS'!AY:AY,PRESUPUESTO!B16) -> 223333.33 | E16: =SUMIFS('MIS FINANZAS'!$AZ:$AZ,'MIS FINANZAS'!AX:AX,PRESUPUESTO!$E$13,'MIS FINANZAS'!AY:AY,PRESUPUESTO!B16) -> 0 | F16: =C16+D16+E16 -> 540000 | G16: =C16*12 -> 3800000 | H16: =D16*12 -> 2680000 | I16: =E16*12 -> 0 | J16: =F16*12 -> 6480000
B17: Provisiones | C17: =SUMIFS('MIS FINANZAS'!$AZ:$AZ,'MIS FINANZAS'!AX:AX,PRESUPUESTO!$C$13,'MIS FINANZAS'!AY:AY,PRESUPUESTO!B17) -> 200000 | D17: =SUMIFS('MIS FINANZAS'!$AZ:$AZ,'MIS FINANZAS'!AX:AX,PRESUPUESTO!$D$13,'MIS FINANZAS'!AY:AY,PRESUPUESTO!B17) -> 0 | E17: =SUMIFS('MIS FINANZAS'!$AZ:$AZ,'MIS FINANZAS'!AX:AX,PRESUPUESTO!$E$13,'MIS FINANZAS'!AY:AY,PRESUPUESTO!B17) -> 0 | F17: =C17+D17+E17 -> 200000 | G17: =C17*12 -> 2400000 | H17: =D17*12 -> 0 | I17: =E17*12 -> 0 | J17: =F17*12 -> 2400000
B18: Deudas entidades | C18: =SUMIFS('MIS FINANZAS'!$AZ:$AZ,'MIS FINANZAS'!AX:AX,PRESUPUESTO!$C$13,'MIS FINANZAS'!AY:AY,PRESUPUESTO!B18) -> 1200000 | D18: =SUMIFS('MIS FINANZAS'!$AZ:$AZ,'MIS FINANZAS'!AX:AX,PRESUPUESTO!$D$13,'MIS FINANZAS'!AY:AY,PRESUPUESTO!B18) -> 0 | E18: =SUMIFS('MIS FINANZAS'!$AZ:$AZ,'MIS FINANZAS'!AX:AX,PRESUPUESTO!$E$13,'MIS FINANZAS'!AY:AY,PRESUPUESTO!B18) -> 0 | F18: =C18+D18+E18 -> 1200000 | G18: =C18*12 -> 14400000 | H18: =D18*12 -> 0 | I18: =E18*12 -> 0 | J18: =F18*12 -> 14400000
B19: Deudas conocidos | C19: =SUMIFS('MIS FINANZAS'!$AZ:$AZ,'MIS FINANZAS'!AX:AX,PRESUPUESTO!$C$13,'MIS FINANZAS'!AY:AY,PRESUPUESTO!B19) -> 0 | D19: =SUMIFS('MIS FINANZAS'!$AZ:$AZ,'MIS FINANZAS'!AX:AX,PRESUPUESTO!$D$13,'MIS FINANZAS'!AY:AY,PRESUPUESTO!B19) -> 0 | E19: =SUMIFS('MIS FINANZAS'!$AZ:$AZ,'MIS FINANZAS'!AX:AX,PRESUPUESTO!$E$13,'MIS FINANZAS'!AY:AY,PRESUPUESTO!B19) -> 0 | F19: =C19+D19+E19 -> 0 | G19: =C19*12 -> 0 | H19: =D19*12 -> 0 | I19: =E19*12 -> 0 | J19: =F19*12 -> 0
B20: Entretenimiento | C20: =SUMIFS('MIS FINANZAS'!$AZ:$AZ,'MIS FINANZAS'!AX:AX,PRESUPUESTO!$C$13,'MIS FINANZAS'!AY:AY,PRESUPUESTO!B20) -> 0 | D20: =SUMIFS('MIS FINANZAS'!$AZ:$AZ,'MIS FINANZAS'!AX:AX,PRESUPUESTO!$D$13,'MIS FINANZAS'!AY:AY,PRESUPUESTO!B20) -> 666666.67 | E20: =SUMIFS('MIS FINANZAS'!$AZ:$AZ,'MIS FINANZAS'!AX:AX,PRESUPUESTO!$E$13,'MIS FINANZAS'!AY:AY,PRESUPUESTO!B20) -> 1050000 | F20: =C20+D20+E20 -> 1716666.7 | G20: =C20*12 -> 0 | H20: =D20*12 -> 8000000 | I20: =E20*12 -> 12600000 | J20: =F20*12 -> 20600000
B21: Familia | C21: =SUMIFS('MIS FINANZAS'!$AZ:$AZ,'MIS FINANZAS'!AX:AX,PRESUPUESTO!$C$13,'MIS FINANZAS'!AY:AY,PRESUPUESTO!B21) -> 550000 | D21: =SUMIFS('MIS FINANZAS'!$AZ:$AZ,'MIS FINANZAS'!AX:AX,PRESUPUESTO!$D$13,'MIS FINANZAS'!AY:AY,PRESUPUESTO!B21) -> 120000 | E21: =SUMIFS('MIS FINANZAS'!$AZ:$AZ,'MIS FINANZAS'!AX:AX,PRESUPUESTO!$E$13,'MIS FINANZAS'!AY:AY,PRESUPUESTO!B21) -> 170000 | F21: =C21+D21+E21 -> 840000 | G21: =C21*12 -> 6600000 | H21: =D21*12 -> 1440000 | I21: =E21*12 -> 2040000 | J21: =F21*12 -> 10080000
B22: Impuestos | C22: =SUMIFS('MIS FINANZAS'!$AZ:$AZ,'MIS FINANZAS'!AX:AX,PRESUPUESTO!$C$13,'MIS FINANZAS'!AY:AY,PRESUPUESTO!B22) -> 108333.33 | D22: =SUMIFS('MIS FINANZAS'!$AZ:$AZ,'MIS FINANZAS'!AX:AX,PRESUPUESTO!$D$13,'MIS FINANZAS'!AY:AY,PRESUPUESTO!B22) -> 0 | E22: =SUMIFS('MIS FINANZAS'!$AZ:$AZ,'MIS FINANZAS'!AX:AX,PRESUPUESTO!$E$13,'MIS FINANZAS'!AY:AY,PRESUPUESTO!B22) -> 0 | F22: =C22+D22+E22 -> 108333.33 | G22: =C22*12 -> 1300000 | H22: =D22*12 -> 0 | I22: =E22*12 -> 0 | J22: =F22*12 -> 1300000
B23: Otros gastos | C23: =SUMIFS('MIS FINANZAS'!$AZ:$AZ,'MIS FINANZAS'!AX:AX,PRESUPUESTO!$C$13,'MIS FINANZAS'!AY:AY,PRESUPUESTO!B23) -> 100000 | D23: =SUMIFS('MIS FINANZAS'!$AZ:$AZ,'MIS FINANZAS'!AX:AX,PRESUPUESTO!$D$13,'MIS FINANZAS'!AY:AY,PRESUPUESTO!B23) -> 655000 | E23: =SUMIFS('MIS FINANZAS'!$AZ:$AZ,'MIS FINANZAS'!AX:AX,PRESUPUESTO!$E$13,'MIS FINANZAS'!AY:AY,PRESUPUESTO!B23) -> 0 | F23: =C23+D23+E23 -> 755000 | G23: =C23*12 -> 1200000 | H23: =D23*12 -> 7860000 | I23: =E23*12 -> 0 | J23: =F23*12 -> 9060000
B24: TOTAL GASTOS | C24: =SUM(C14:C23) -> 5060000 | D24: =SUM(D14:D23) -> 1665000 | E24: =SUM(E14:E23) -> 1620000 | F24: =SUM(F14:F23) -> 8345000 | G24: =SUM(G14:G23) -> 60720000 | H24: =SUM(H14:H23) -> 19980000 | I24: =SUM(I14:I23) -> 19440000 | J24: =SUM(J14:J23) -> 100140000
C26: FIJO | D26: VARIABLE | F26: TOTAL | G26: FIJO | H26: VARIABLE | J26: TOTAL
B27: FLUJO DE CAJA LIBRE | C27: =C12-C24 -> -726666.67 | D27: =D12-(D24+E24) -> -418333.33 | F27: =F12-F24 -> -1145000 | G27: =G12-G24 -> -8720000 | H27: =H12-(H24+I24) -> -5020000 | J27: =J12-J24 -> -13740000
B28: INDICADOR | C28: =C12/C24 -> 0.85638999 | D28: =D12/(D24+E24) -> 0.87265348 | F28: =F12/F24 -> 0.86279209 | G28: =G12/G24 -> 0.85638999 | H28: =H12/(H24+I24) -> 0.87265348 | J28: =J12/J24 -> 0.86279209
B30: INGRESOS
B31: Salario | C31: =F8/$F$12 -> 0.55555556
B32: Negocio | C32: =F9/$F$12 -> 0.16203704
B33: Inversión | C33: =F10/$F$12 -> 0.023148148
B34: Otros ingresos | C34: =F11/$F$12 -> 0.25925926
B36: GASTOS
B37: Hogar | C37: =F14/$F$24 -> 0.24985021
B38: Alimentación | C38: =F15/$F$24 -> 0.10784901
B39: Transporte | C39: =F16/$F$24 -> 0.064709407
B40: Provisiones | C40: =F17/$F$24 -> 0.023966447
B41: Deudas con entidades | C41: =F18/$F$24 -> 0.14379868
B42: Deudas con amigos | C42: =F19/$F$24 -> 0
B43: Entretenimiento | C43: =F20/$F$24 -> 0.205712
B44: Familia | C44: =F21/$F$24 -> 0.10065908
B45: Impuestos | C45: =F22/$F$24 -> 0.012981825
B46: Otros gastos | C46: =F23/$F$24 -> 0.090473337
B48: TIPOS DE INGRESO
B49: Fijo | C49: =D49/$F$12 -> 0.60185185 | D49: =SUMIF('MIS FINANZAS'!$AU$7:$AU$103,PRESUPUESTO!B49,'MIS FINANZAS'!$AW$7:$AW$103) -> 4333333.3
...

Sheet OPORTUNIDADES DE MEJORA
C6: ACTUAL (MES) | D6: MEJORA (MES)
B7: No necesarios | C7: =SUMIF(C17:C118,"No necesario",D17:D118) -> 1620000 | D7: =SUMIF(C17:C118,"No necesario",E17:E118) -> 500000
B8: No tan necesarios | C8: =SUMIF(C17:C118,"No tan necesario",D17:D118) -> 1665000 | D8: =SUMIF(C17:C118,"No tan necesario",E17:E118) -> 715000
B9: TOTAL GASTOS VARIABLES | C9: =C8+C7 -> 3285000 | D9: =D8+D7 -> 1215000
B10: FLUJO DE CAJA LIBRE | C10: =PRESUPUESTO!F27 -> -1145000 | D10: =(C9-D9)+C10 -> 925000
E12: AHORRO AÑO
B13: TOTAL AHORRO | C13: =D10-C10 -> 2070000 | E13: =C13*12 -> 24840000
B16: GASTOS VARIABLES | C16: TIPO | D16: GASTO MENSUAL | E16: NUEVO GASTO MENSUAL | AE16: =LOOKUP(1000000,Y:Y) -> 5
B17: =AL17 -> Internet y telefono | C17: =AM17 -> No necesario | D17: =AN17 -> 120000 | E17: 50000 | Y17: =IFERROR(IF(Z17<>"",1+Y16,""),0) -> 1 | Z17: =IFERROR(__xludf.DUMMYFUNCTION("FILTER('MIS FINANZAS'!$H$7:$I$103,'MIS FINANZAS'!$I$7:$I$103=""No necesario"")"),"Internet y telefono") -> Internet y telefono | AA17: =IFERROR(__xludf.DUMMYFUNCTION("""COMPUTED_VALUE"""),"No necesario") -> No necesario | AB17: =IFERROR(VLOOKUP(Z17,'MIS FINANZAS'!$H$7:$J$103,3,0),"") -> Mensual | AC17: =IFERROR(VLOOKUP(Z17,'MIS FINANZAS'!$H$7:$L$103,5,0),"") -> 120000 | AD17: =IF(AB17="Bimensual",AC17/2,IF(AB17="Trimestral",AC17/3,IF(AB17="Semestral",AC17/6,IF(AB17="Anual",AC17/12,AC17)))) -> 120000 | AE17: =IF(AF17<>"",1+AE16,"") -> 6 | AF17: =IFERROR(__xludf.DUMMYFUNCTION("FILTER('MIS FINANZAS'!$H$7:$I$103,'MIS FINANZAS'!$I$7:$I$103=""No tan necesario"")"),"Plan de datos") -> Plan de datos | AG17: =IFERROR(__xludf.DUMMYFUNCTION("""COMPUTED_VALUE"""),"No tan necesario") -> No tan necesario | AH17: =IFERROR(VLOOKUP(AF17,'MIS FINANZAS'!$H$7:$J$103,3,0),"") -> Mensual | AI17: =IFERROR(VLOOKUP(AF17,'MIS FINANZAS'!$H$7:$L$103,5,0),"") -> 80000 | AJ17: =IF(AH17="Bimensual",AI17/2,IF(AH17="Trimestral",AI17/3,IF(AH17="Semestral",AI17/6,IF(AH17="Anual",AI17/12,AI17)))) -> 80000 | AK17: 1 | AL17: =IFERROR(IFERROR(VLOOKUP(AK17,$Y:$AA,2,0),VLOOKUP(AK17,$AE:$AG,2,0)),"") -> Internet y telefono | AM17: =IFERROR(IFERROR(VLOOKUP(AK17,$Y:$AA,3,0),VLOOKUP(AK17,$AE:$AG,3,0)),"") -> No necesario | AN17: =IFERROR(IFERROR(VLOOKUP(AK17,$Y:$AD,6,0),VLOOKUP(AK17,$AE:$AJ,6,0)),"") -> 120000 | AO17: =IFERROR(IFERROR(VLOOKUP(AK17,$Y:$AD,4,0),VLOOKUP(AK17,$AE:$AJ,4,0)),"") -> Mensual | AP17: =E17 -> 50000 | AQ17: =IF(AO17="Bimensual",AP17*2,IF(AO17="Trimestral",AP17*3,IF(AO17="Semestral",AP17*6,IF(AO17="Anual",AP17*12,AP17)))) -> 50000
B18: =AL18 -> Restaurantes | C18: =AM18 -> No necesario | D18: =AN18 -> 600000 | E18: 200000 | Y18: =IF(Z18<>"",1+Y17,"") -> 2 | Z18: =IFERROR(__xludf.DUMMYFUNCTION("""COMPUTED_VALUE"""),"Restaurantes") -> Restaurantes | AA18: =IFERROR(__xludf.DUMMYFUNCTION("""COMPUTED_VALUE"""),"No necesario") -> No necesario | AB18: =IFERROR(VLOOKUP(Z18,'MIS FINANZAS'!$H$7:$J$103,3,0),"") -> Mensual | AC18: =IFERROR(VLOOKUP(Z18,'MIS FINANZAS'!$H$7:$L$103,5,0),"") -> 600000 | AD18: =IF(AB18="Bimensual",AC18/2,IF(AB18="Trimestral",AC18/3,IF(AB18="Semestral",AC18/6,IF(AB18="Anual",AC18/12,AC18)))) -> 600000 | AE18: =IF(AF18<>"",1+AE17,"") -> 7 | AF18: =IFERROR(__xludf.DUMMYFUNCTION("""COMPUTED_VALUE"""),"Seguro carro") -> Seguro carro | AG18: =IFERROR(__xludf.DUMMYFUNCTION("""COMPUTED_VALUE"""),"No tan necesario") -> No tan necesario | AH18: =IFERROR(VLOOKUP(AF18,'MIS FINANZAS'!$H$7:$J$103,3,0),"") -> Anual | AI18: =IFERROR(VLOOKUP(AF18,'MIS FINANZAS'!$H$7:$L$103,5,0),"") -> 1000000 | AJ18: =IF(AH18="Bimensual",AI18/2,IF(AH18="Trimestral",AI18/3,IF(AH18="Semestral",AI18/6,IF(AH18="Anual",AI18/12,AI18)))) -> 83333.333 | AK18: 2 | AL18: =IFERROR(IFERROR(VLOOKUP(AK18,$Y:$AA,2,0),VLOOKUP(AK18,$AE:$AG,2,0)),"") -> Restaurantes | AM18: =IFERROR(IFERROR(VLOOKUP(AK18,$Y:$AA,3,0),VLOOKUP(AK18,$AE:$AG,3,0)),"") -> No necesario | AN18: =IFERROR(IFERROR(VLOOKUP(AK18,$Y:$AD,6,0),VLOOKUP(AK18,$AE:$AJ,6,0)),"") -> 600000 | AO18: =IFERROR(IFERROR(VLOOKUP(AK18,$Y:$AD,4,0),VLOOKUP(AK18,$AE:$AJ,4,0)),"") -> Mensual | AP18: =E18 -> 200000 | AQ18: =IF(AO18="Bimensual",AP18*2,IF(AO18="Trimestral",AP18*3,IF(AO18="Semestral",AP18*6,IF(AO18="Anual",AP18*12,AP18)))) -> 200000
B19: =AL19 -> Centro comercial | C19: =AM19 -> No necesario | D19: =AN19 -> 450000 | E19: 150000 | Y19: =IF(Z19<>"",1+Y18,"") -> 3 | Z19: =IFERROR(__xludf.DUMMYFUNCTION("""COMPUTED_VALUE"""),"Centro comercial") -> Centro comercial | AA19: =IFERROR(__xludf.DUMMYFUNCTION("""COMPUTED_VALUE"""),"No necesario") -> No necesario | AB19: =IFERROR(VLOOKUP(Z19,'MIS FINANZAS'!$H$7:$J$103,3,0),"") -> Mensual | AC19: =IFERROR(VLOOKUP(Z19,'MIS FINANZAS'!$H$7:$L$103,5,0),"") -> 450000 | AD19: =IF(AB19="Bimensual",AC19/2,IF(AB19="Trimestral",AC19/3,IF(AB19="Semestral",AC19/6,IF(AB19="Anual",AC19/12,AC19)))) -> 450000 | AE19: =IF(AF19<>"",1+AE18,"") -> 8 | AF19: =IFERROR(__xludf.DUMMYFUNCTION("""COMPUTED_VALUE"""),"Gimnasio") -> Gimnasio | AG19: =IFERROR(__xludf.DUMMYFUNCTION("""COMPUTED_VALUE"""),"No tan necesario") -> No tan necesario | AH19: =IFERROR(VLOOKUP(AF19,'MIS FINANZAS'!$H$7:$J$103,3,0),"") -> Anual | AI19: =IFERROR(VLOOKUP(AF19,'MIS FINANZAS'!$H$7:$L$103,5,0),"") -> 900000 | AJ19: =IF(AH19="Bimensual",AI19/2,IF(AH19="Trimestral",AI19/3,IF(AH19="Semestral",AI19/6,IF(AH19="Anual",AI19/12,AI19)))) -> 75000 | AK19: 3 | AL19: =IFERROR(IFERROR(VLOOKUP(AK19,$Y:$AA,2,0),VLOOKUP(AK19,$AE:$AG,2,0)),"") -> Centro comercial | AM19: =IFERROR(IFERROR(VLOOKUP(AK19,$Y:$AA,3,0),VLOOKUP(AK19,$AE:$AG,3,0)),"") -> No necesario | AN19: =IFERROR(IFERROR(VLOOKUP(AK19,$Y:$AD,6,0),VLOOKUP(AK19,$AE:$AJ,6,0)),"") -> 450000 | AO19: =IFERROR(IFERROR(VLOOKUP(AK19,$Y:$AD,4,0),VLOOKUP(AK19,$AE:$AJ,4,0)),"") -> Mensual | AP19: =E19 -> 150000 | AQ19: =IF(AO19="Bimensual",AP19*2,IF(AO19="Trimestral",AP19*3,IF(AO19="Semestral",AP19*6,IF(AO19="Anual",AP19*12,AP19)))) -> 150000
B20: =AL20 -> Juguetes perritos | C20: =AM20 -> No necesario | D20: =AN20 -> 50000 | E20: 0 | Y20: =IF(Z20<>"",1+Y19,"") -> 4 | Z20: =IFERROR(__xludf.DUMMYFUNCTION("""COMPUTED_VALUE"""),"Juguetes perritos") -> Juguetes perritos | AA20: =IFERROR(__xludf.DUMMYFUNCTION("""COMPUTED_VALUE"""),"No necesario") -> No necesario | AB20: =IFERROR(VLOOKUP(Z20,'MIS FINANZAS'!$H$7:$J$103,3,0),"") -> Bimensual | AC20: =IFERROR(VLOOKUP(Z20,'MIS FINANZAS'!$H$7:$L$103,5,0),"") -> 100000 | AD20: =IF(AB20="Bimensual",AC20/2,IF(AB20="Trimestral",AC20/3,IF(AB20="Semestral",AC20/6,IF(AB20="Anual",AC20/12,AC20)))) -> 50000 | AE20: =IF(AF20<>"",1+AE19,"") -> 9 | AF20: =IFERROR(__xludf.DUMMYFUNCTION("""COMPUTED_VALUE"""),"Streaming (Netflix, spotify…)") -> Streaming (Netflix, spotify…) | AG20: =IFERROR(__xludf.DUMMYFUNCTION("""COMPUTED_VALUE"""),"No tan necesario") -> No tan necesario | AH20: =IFERROR(VLOOKUP(AF20,'MIS FINANZAS'!$H$7:$J$103,3,0),"") -> Mensual | AI20: =IFERROR(VLOOKUP(AF20,'MIS FINANZAS'!$H$7:$L$103,5,0),"") -> 120000 | AJ20: =IF(AH20="Bimensual",AI20/2,IF(AH20="Trimestral",AI20/3,IF(AH20="Semestral",AI20/6,IF(AH20="Anual",AI20/12,AI20)))) -> 120000 | AK20: 4 | AL20: =IFERROR(IFERROR(VLOOKUP(AK20,$Y:$AA,2,0),VLOOKUP(AK20,$AE:$AG,2,0)),"") -> Juguetes perritos | AM20: =IFERROR(IFERROR(VLOOKUP(AK20,$Y:$AA,3,0),VLOOKUP(AK20,$AE:$AG,3,0)),"") -> No necesario | AN20: =IFERROR(IFERROR(VLOOKUP(AK20,$Y:$AD,6,0),VLOOKUP(AK20,$AE:$AJ,6,0)),"") -> 50000 | AO20: =IFERROR(IFERROR(VLOOKUP(AK20,$Y:$AD,4,0),VLOOKUP(AK20,$AE:$AJ,4,0)),"") -> Bimensual | AP20: =E20 -> 0 | AQ20: =IF(AO20="Bimensual",AP20*2,IF(AO20="Trimestral",AP20*3,IF(AO20="Semestral",AP20*6,IF(AO20="Anual",AP20*12,AP20)))) -> 0
B21: =AL21 -> Domicilios | C21: =AM21 -> No necesario | D21: =AN21 -> 400000 | E21: 100000 | Y21: =IF(Z21<>"",1+Y20,"") -> 5 | Z21: =IFERROR(__xludf.DUMMYFUNCTION("""COMPUTED_VALUE"""),"Domicilios") -> Domicilios | AA21: =IFERROR(__xludf.DUMMYFUNCTION("""COMPUTED_VALUE"""),"No necesario") -> No necesario | AB21: =IFERROR(VLOOKUP(Z21,'MIS FINANZAS'!$H$7:$J$103,3,0),"") -> Mensual | AC21: =IFERROR(VLOOKUP(Z21,'MIS FINANZAS'!$H$7:$L$103,5,0),"") -> 400000 | AD21: =IF(AB21="Bimensual",AC21/2,IF(AB21="Trimestral",AC21/3,IF(AB21="Semestral",AC21/6,IF(AB21="Anual",AC21/12,AC21)))) -> 400000 | AE21: =IF(AF21<>"",1+AE20,"") -> 10 | AF21: =IFERROR(__xludf.DUMMYFUNCTION("""COMPUTED_VALUE"""),"Taxi/Uber/Bus") -> Taxi/Uber/Bus | AG21: =IFERROR(__xludf.DUMMYFUNCTION("""COMPUTED_VALUE"""),"No tan necesario") -> No tan necesario | AH21: =IFERROR(VLOOKUP(AF21,'MIS FINANZAS'!$H$7:$J$103,3,0),"") -> Mensual | AI21: =IFERROR(VLOOKUP(AF21,'MIS FINANZAS'!$H$7:$L$103,5,0),"") -> 140000 | AJ21: =IF(AH21="Bimensual",AI21/2,IF(AH21="Trimestral",AI21/3,IF(AH21="Semestral",AI21/6,IF(AH21="Anual",AI21/12,AI21)))) -> 140000 | AK21: 5 | AL21: =IFERROR(IFERROR(VLOOKUP(AK21,$Y:$AA,2,0),VLOOKUP(AK21,$AE:$AG,2,0)),"") -> Domicilios | AM21: =IFERROR(IFERROR(VLOOKUP(AK21,$Y:$AA,3,0),VLOOKUP(AK21,$AE:$AG,3,0)),"") -> No necesario | AN21: =IFERROR(IFERROR(VLOOKUP(AK21,$Y:$AD,6,0),VLOOKUP(AK21,$AE:$AJ,6,0)),"") -> 400000 | AO21: =IFERROR(IFERROR(VLOOKUP(AK21,$Y:$AD,4,0),VLOOKUP(AK21,$AE:$AJ,4,0)),"") -> Mensual | AP21: =E21 -> 100000 | AQ21: =IF(AO21="Bimensual",AP21*2,IF(AO21="Trimestral",AP21*3,IF(AO21="Semestral",AP21*6,IF(AO21="Anual",AP21*12,AP21)))) -> 100000
B22: =AL22 -> Plan de datos | C22: =AM22 -> No tan necesario | D22: =AN22 -> 80000 | E22: 80000 | Y22: =IF(Z22<>"",1+Y21,"") | AB22: =IFERROR(VLOOKUP(Z22,'MIS FINANZAS'!$H$7:$J$103,3,0),"") | AC22: =IFERROR(VLOOKUP(Z22,'MIS FINANZAS'!$H$7:$L$103,5,0),"") | AD22: =IF(AB22="Bimensual",AC22/2,IF(AB22="Trimestral",AC22/3,IF(AB22="Semestral",AC22/6,IF(AB22="Anual",AC22/12,AC22)))) | AE22: =IF(AF22<>"",1+AE21,"") -> 11 | AF22: =IFERROR(__xludf.DUMMYFUNCTION("""COMPUTED_VALUE"""),"Viajes") -> Viajes | AG22: =IFERROR(__xludf.DUMMYFUNCTION("""COMPUTED_VALUE"""),"No tan necesario") -> No tan necesario | AH22: =IFERROR(VLOOKUP(AF22,'MIS FINANZAS'!$H$7:$J$103,3,0),"") -> Semestral | AI22: =IFERROR(VLOOKUP(AF22,'MIS FINANZAS'!$H$7:$L$103,5,0),"") -> 4000000 | AJ22: =IF(AH22="Bimensual",AI22/2,IF(AH22="Trimestral",AI22/3,IF(AH22="Semestral",AI22/6,IF(AH22="Anual",AI22/12,AI22)))) -> 666666.67 | AK22: 6 | AL22: =IFERROR(IFERROR(VLOOKUP(AK22,$Y:$AA,2,0),VLOOKUP(AK22,$AE:$AG,2,0)),"") -> Plan de datos | AM22: =IFERROR(IFERROR(VLOOKUP(AK22,$Y:$AA,3,0),VLOOKUP(AK22,$AE:$AG,3,0)),"") -> No tan necesario | AN22: =IFERROR(IFERROR(VLOOKUP(AK22,$Y:$AD,6,0),VLOOKUP(AK22,$AE:$AJ,6,0)),"") -> 80000 | AO22: =IFERROR(IFERROR(VLOOKUP(AK22,$Y:$AD,4,0),VLOOKUP(AK22,$AE:$AJ,4,0)),"") -> Mensual | AP22: =E22 -> 80000 | AQ22: =IF(AO22="Bimensual",AP22*2,IF(AO22="Trimestral",AP22*3,IF(AO22="Semestral",AP22*6,IF(AO22="Anual",AP22*12,AP22)))) -> 80000
B23: =AL23 -> Seguro carro | C23: =AM23 -> No tan necesario | D23: =AN23 -> 83333.333 | E23: 50000 | Y23: =IF(Z23<>"",1+Y22,"") | AB23: =IFERROR(VLOOKUP(Z23,'MIS FINANZAS'!$H$7:$J$103,3,0),"") | AC23: =IFERROR(VLOOKUP(Z23,'MIS FINANZAS'!$H$7:$L$103,5,0),"") | AD23: =IF(AB23="Bimensual",AC23/2,IF(AB23="Trimestral",AC23/3,IF(AB23="Semestral",AC23/6,IF(AB23="Anual",AC23/12,AC23)))) | AE23: =IF(AF23<>"",1+AE22,"") -> 12 | AF23: =IFERROR(__xludf.DUMMYFUNCTION("""COMPUTED_VALUE"""),"Ropa") -> Ropa | AG23: =IFERROR(__xludf.DUMMYFUNCTION("""COMPUTED_VALUE"""),"No tan necesario") -> No tan necesario | AH23: =IFERROR(VLOOKUP(AF23,'MIS FINANZAS'!$H$7:$J$103,3,0),"") -> Trimestral | AI23: =IFERROR(VLOOKUP(AF23,'MIS FINANZAS'!$H$7:$L$103,5,0),"") -> 1500000 | AJ23: =IF(AH23="Bimensual",AI23/2,IF(AH23="Trimestral",AI23/3,IF(AH23="Semestral",AI23/6,IF(AH23="Anual",AI23/12,AI23)))) -> 500000 | AK23: 7 | AL23: =IFERROR(IFERROR(VLOOKUP(AK23,$Y:$AA,2,0),VLOOKUP(AK23,$AE:$AG,2,0)),"") -> Seguro carro | AM23: =IFERROR(IFERROR(VLOOKUP(AK23,$Y:$AA,3,0),VLOOKUP(AK23,$AE:$AG,3,0)),"") -> No tan necesario | AN23: =IFERROR(IFERROR(VLOOKUP(AK23,$Y:$AD,6,0),VLOOKUP(AK23,$AE:$AJ,6,0)),"") -> 83333.333 | AO23: =IFERROR(IFERROR(VLOOKUP(AK23,$Y:$AD,4,0),VLOOKUP(AK23,$AE:$AJ,4,0)),"") -> Anual | AP23: =E23 -> 50000 | AQ23: =IF(AO23="Bimensual",AP23*2,IF(AO23="Trimestral",AP23*3,IF(AO23="Semestral",AP23*6,IF(AO23="Anual",AP23*12,AP23)))) -> 600000
B24: =AL24 -> Gimnasio | C24: =AM24 -> No tan necesario | D24: =AN24 -> 75000 | E24: 30000 | Y24: =IF(Z24<>"",1+Y23,"") | AB24: =IFERROR(VLOOKUP(Z24,'MIS FINANZAS'!$H$7:$J$103,3,0),"") | AC24: =IFERROR(VLOOKUP(Z24,'MIS FINANZAS'!$H$7:$L$103,5,0),"") | AD24: =IF(AB24="Bimensual",AC24/2,IF(AB24="Trimestral",AC24/3,IF(AB24="Semestral",AC24/6,IF(AB24="Anual",AC24/12,AC24)))) | AE24: =IF(AF24<>"",1+AE23,"") | AH24: =IFERROR(VLOOKUP(AF24,'MIS FINANZAS'!$H$7:$J$103,3,0),"") | AI24: =IFERROR(VLOOKUP(AF24,'MIS FINANZAS'!$H$7:$L$103,5,0),"") | AJ24: =IF(AH24="Bimensual",AI24/2,IF(AH24="Trimestral",AI24/3,IF(AH24="Semestral",AI24/6,IF(AH24="Anual",AI24/12,AI24)))) | AK24: 8 | AL24: =IFERROR(IFERROR(VLOOKUP(AK24,$Y:$AA,2,0),VLOOKUP(AK24,$AE:$AG,2,0)),"") -> Gimnasio | AM24: =IFERROR(IFERROR(VLOOKUP(AK24,$Y:$AA,3,0),VLOOKUP(AK24,$AE:$AG,3,0)),"") -> No tan necesario | AN24: =IFERROR(IFERROR(VLOOKUP(AK24,$Y:$AD,6,0),VLOOKUP(AK24,$AE:$AJ,6,0)),"") -> 75000 | AO24: =IFERROR(IFERROR(VLOOKUP(AK24,$Y:$AD,4,0),VLOOKUP(AK24,$AE:$AJ,4,0)),"") -> Anual | AP24: =E24 -> 30000 | AQ24: =IF(AO24="Bimensual",AP24*2,IF(AO24="Trimestral",AP24*3,IF(AO24="Semestral",AP24*6,IF(AO24="Anual",AP24*12,AP24)))) -> 360000
B25: =AL25 -> Streaming (Netflix, spotify…) | C25: =AM25 -> No tan necesario | D25: =AN25 -> 120000 | E25: 40000 | Y25: =IF(Z25<>"",1+Y24,"") | AB25: =IFERROR(VLOOKUP(Z25,'MIS FINANZAS'!$H$7:$J$103,3,0),"") | AC25: =IFERROR(VLOOKUP(Z25,'MIS FINANZAS'!$H$7:$L$103,5,0),"") | AD25: =IF(AB25="Bimensual",AC25/2,IF(AB25="Trimestral",AC25/3,IF(AB25="Semestral",AC25/6,IF(AB25="Anual",AC25/12,AC25)))) | AE25: =IF(AF25<>"",1+AE24,"") | AH25: =IFERROR(VLOOKUP(AF25,'MIS FINANZAS'!$H$7:$J$103,3,0),"") | AI25: =IFERROR(VLOOKUP(AF25,'MIS FINANZAS'!$H$7:$L$103,5,0),"") | AJ25: =IF(AH25="Bimensual",AI25/2,IF(AH25="Trimestral",AI25/3,IF(AH25="Semestral",AI25/6,IF(AH25="Anual",AI25/12,AI25)))) | AK25: 9 | AL25: =IFERROR(IFERROR(VLOOKUP(AK25,$Y:$AA,2,0),VLOOKUP(AK25,$AE:$AG,2,0)),"") -> Streaming (Netflix, spotify…) | AM25: =IFERROR(IFERROR(VLOOKUP(AK25,$Y:$AA,3,0),VLOOKUP(AK25,$AE:$AG,3,0)),"") -> No tan necesario | AN25: =IFERROR(IFERROR(VLOOKUP(AK25,$Y:$AD,6,0),VLOOKUP(AK25,$AE:$AJ,6,0)),"") -> 120000 | AO25: =IFERROR(IFERROR(VLOOKUP(AK25,$Y:$AD,4,0),VLOOKUP(AK25,$AE:$AJ,4,0)),"") -> Mensual | AP25: =E25 -> 40000 | AQ25: =IF(AO25="Bimensual",AP25*2,IF(AO25="Trimestral",AP25*3,IF(AO25="Semestral",AP25*6,IF(AO25="Anual",AP25*12,AP25)))) -> 40000
B26: =AL26 -> Taxi/Uber/Bus | C26: =AM26 -> No tan necesario | D26: =AN26 -> 140000 | E26: 65000 | Y26: =IF(Z26<>"",1+Y25,"") | AB26: =IFERROR(VLOOKUP(Z26,'MIS FINANZAS'!$H$7:$J$103,3,0),"") | AC26: =IFERROR(VLOOKUP(Z26,'MIS FINANZAS'!$H$7:$L$103,5,0),"") | AD26: =IF(AB26="Bimensual",AC26/2,IF(AB26="Trimestral",AC26/3,IF(AB26="Semestral",AC26/6,IF(AB26="Anual",AC26/12,AC26)))) | AE26: =IF(AF26<>"",1+AE25,"") | AH26: =IFERROR(VLOOKUP(AF26,'MIS FINANZAS'!$H$7:$J$103,3,0),"") | AI26: =IFERROR(VLOOKUP(AF26,'MIS FINANZAS'!$H$7:$L$103,5,0),"") | AJ26: =IF(AH26="Bimensual",AI26/2,IF(AH26="Trimestral",AI26/3,IF(AH26="Semestral",AI26/6,IF(AH26="Anual",AI26/12,AI26)))) | AK26: 10 | AL26: =IFERROR(IFERROR(VLOOKUP(AK26,$Y:$AA,2,0),VLOOKUP(AK26,$AE:$AG,2,0)),"") -> Taxi/Uber/Bus | AM26: =IFERROR(IFERROR(VLOOKUP(AK26,$Y:$AA,3,0),VLOOKUP(AK26,$AE:$AG,3,0)),"") -> No tan necesario | AN26: =IFERROR(IFERROR(VLOOKUP(AK26,$Y:$AD,6,0),VLOOKUP(AK26,$AE:$AJ,6,0)),"") -> 140000 | AO26: =IFERROR(IFERROR(VLOOKUP(AK26,$Y:$AD,4,0),VLOOKUP(AK26,$AE:$AJ,4,0)),"") -> Mensual | AP26: =E26 -> 65000 | AQ26: =IF(AO26="Bimensual",AP26*2,IF(AO26="Trimestral",AP26*3,IF(AO26="Semestral",AP26*6,IF(AO26="Anual",AP26*12,AP26)))) -> 65000
B27: =AL27 -> Viajes | C27: =AM27 -> No tan necesario | D27: =AN27 -> 666666.67 | E27: 300000 | Y27: =IF(Z27<>"",1+Y26,"") | AB27: =IFERROR(VLOOKUP(Z27,'MIS FINANZAS'!$H$7:$J$103,3,0),"") | AC27: =IFERROR(VLOOKUP(Z27,'MIS FINANZAS'!$H$7:$L$103,5,0),"") | AD27: =IF(AB27="Bimensual",AC27/2,IF(AB27="Trimestral",AC27/3,IF(AB27="Semestral",AC27/6,IF(AB27="Anual",AC27/12,AC27)))) | AE27: =IF(AF27<>"",1+AE26,"") | AH27: =IFERROR(VLOOKUP(AF27,'MIS FINANZAS'!$H$7:$J$103,3,0),"") | AI27: =IFERROR(VLOOKUP(AF27,'MIS FINANZAS'!$H$7:$L$103,5,0),"") | AJ27: =IF(AH27="Bimensual",AI27/2,IF(AH27="Trimestral",AI27/3,IF(AH27="Semestral",AI27/6,IF(AH27="Anual",AI27/12,AI27)))) | AK27: 11 | AL27: =IFERROR(IFERROR(VLOOKUP(AK27,$Y:$AA,2,0),VLOOKUP(AK27,$AE:$AG,2,0)),"") -> Viajes | AM27: =IFERROR(IFERROR(VLOOKUP(AK27,$Y:$AA,3,0),VLOOKUP(AK27,$AE:$AG,3,0)),"") -> No tan necesario | AN27: =IFERROR(IFERROR(VLOOKUP(AK27,$Y:$AD,6,0),VLOOKUP(AK27,$AE:$AJ,6,0)),"") -> 666666.67 | AO27: =IFERROR(IFERROR(VLOOKUP(AK27,$Y:$AD,4,0),VLOOKUP(AK27,$AE:$AJ,4,0)),"") -> Semestral | AP27: =E27 -> 300000 | AQ27: =IF(AO27="Bimensual",AP27*2,IF(AO27="Trimestral",AP27*3,IF(AO27="Semestral",AP27*6,IF(AO27="Anual",AP27*12,AP27)))) -> 1800000
B28: =AL28 -> Ropa | C28: =AM28 -> No tan necesario | D28: =AN28 -> 500000 | E28: 150000 | Y28: =IF(Z28<>"",1+Y27,"") | AB28: =IFERROR(VLOOKUP(Z28,'MIS FINANZAS'!$H$7:$J$103,3,0),"") | AC28: =IFERROR(VLOOKUP(Z28,'MIS FINANZAS'!$H$7:$L$103,5,0),"") | AD28: =IF(AB28="Bimensual",AC28/2,IF(AB28="Trimestral",AC28/3,IF(AB28="Semestral",AC28/6,IF(AB28="Anual",AC28/12,AC28)))) | AE28: =IF(AF28<>"",1+AE27,"") | AH28: =IFERROR(VLOOKUP(AF28,'MIS FINANZAS'!$H$7:$J$103,3,0),"") | AI28: =IFERROR(VLOOKUP(AF28,'MIS FINANZAS'!$H$7:$L$103,5,0),"") | AJ28: =IF(AH28="Bimensual",AI28/2,IF(AH28="Trimestral",AI28/3,IF(AH28="Semestral",AI28/6,IF(AH28="Anual",AI28/12,AI28)))) | AK28: 12 | AL28: =IFERROR(IFERROR(VLOOKUP(AK28,$Y:$AA,2,0),VLOOKUP(AK28,$AE:$AG,2,0)),"") -> Ropa | AM28: =IFERROR(IFERROR(VLOOKUP(AK28,$Y:$AA,3,0),VLOOKUP(AK28,$AE:$AG,3,0)),"") -> No tan necesario | AN28: =IFERROR(IFERROR(VLOOKUP(AK28,$Y:$AD,6,0),VLOOKUP(AK28,$AE:$AJ,6,0)),"") -> 500000 | AO28: =IFERROR(IFERROR(VLOOKUP(AK28,$Y:$AD,4,0),VLOOKUP(AK28,$AE:$AJ,4,0)),"") -> Trimestral | AP28: =E28 -> 150000 | AQ28: =IF(AO28="Bimensual",AP28*2,IF(AO28="Trimestral",AP28*3,IF(AO28="Semestral",AP28*6,IF(AO28="Anual",AP28*12,AP28)))) -> 450000
B29: =AL29 | C29: =AM29 | D29: =AN29 | Y29: =IF(Z29<>"",1+Y28,"") | AB29: =IFERROR(VLOOKUP(Z29,'MIS FINANZAS'!$H$7:$J$103,3,0),"") | AC29: =IFERROR(VLOOKUP(Z29,'MIS FINANZAS'!$H$7:$L$103,5,0),"") | AD29: =IF(AB29="Bimensual",AC29/2,IF(AB29="Trimestral",AC29/3,IF(AB29="Semestral",AC29/6,IF(AB29="Anual",AC29/12,AC29)))) | AE29: =IF(AF29<>"",1+AE28,"") | AH29: =IFERROR(VLOOKUP(AF29,'MIS FINANZAS'!$H$7:$J$103,3,0),"") | AI29: =IFERROR(VLOOKUP(AF29,'MIS FINANZAS'!$H$7:$L$103,5,0),"") | AJ29: =IF(AH29="Bimensual",AI29/2,IF(AH29="Trimestral",AI29/3,IF(AH29="Semestral",AI29/6,IF(AH29="Anual",AI29/12,AI29)))) | AK29: 13 | AL29: =IFERROR(IFERROR(VLOOKUP(AK29,$Y:$AA,2,0),VLOOKUP(AK29,$AE:$AG,2,0)),"") | AM29: =IFERROR(IFERROR(VLOOKUP(AK29,$Y:$AA,3,0),VLOOKUP(AK29,$AE:$AG,3,0)),"") | AN29: =IFERROR(IFERROR(VLOOKUP(AK29,$Y:$AD,6,0),VLOOKUP(AK29,$AE:$AJ,6,0)),"") | AO29: =IFERROR(IFERROR(VLOOKUP(AK29,$Y:$AD,4,0),VLOOKUP(AK29,$AE:$AJ,4,0)),"") | AP29: =E29 | AQ29: =IF(AO29="Bimensual",AP29*2,IF(AO29="Trimestral",AP29*3,IF(AO29="Semestral",AP29*6,IF(AO29="Anual",AP29*12,AP29))))
B30: =AL30 | C30: =AM30 | D30: =AN30 | Y30: =IF(Z30<>"",1+Y29,"") | AB30: =IFERROR(VLOOKUP(Z30,'MIS FINANZAS'!$H$7:$J$103,3,0),"") | AC30: =IFERROR(VLOOKUP(Z30,'MIS FINANZAS'!$H$7:$L$103,5,0),"") | AD30: =IF(AB30="Bimensual",AC30/2,IF(AB30="Trimestral",AC30/3,IF(AB30="Semestral",AC30/6,IF(AB30="Anual",AC30/12,AC30)))) | AE30: =IF(AF30<>"",1+AE29,"") | AH30: =IFERROR(VLOOKUP(AF30,'MIS FINANZAS'!$H$7:$J$103,3,0),"") | AI30: =IFERROR(VLOOKUP(AF30,'MIS FINANZAS'!$H$7:$L$103,5,0),"") | AJ30: =IF(AH30="Bimensual",AI30/2,IF(AH30="Trimestral",AI30/3,IF(AH30="Semestral",AI30/6,IF(AH30="Anual",AI30/12,AI30)))) | AK30: 14 | AL30: =IFERROR(IFERROR(VLOOKUP(AK30,$Y:$AA,2,0),VLOOKUP(AK30,$AE:$AG,2,0)),"") | AM30: =IFERROR(IFERROR(VLOOKUP(AK30,$Y:$AA,3,0),VLOOKUP(AK30,$AE:$AG,3,0)),"") | AN30: =IFERROR(IFERROR(VLOOKUP(AK30,$Y:$AD,6,0),VLOOKUP(AK30,$AE:$AJ,6,0)),"") | AO30: =IFERROR(IFERROR(VLOOKUP(AK30,$Y:$AD,4,0),VLOOKUP(AK30,$AE:$AJ,4,0)),"") | AP30: =E30 | AQ30: =IF(AO30="Bimensual",AP30*2,IF(AO30="Trimestral",AP30*3,IF(AO30="Semestral",AP30*6,IF(AO30="Anual",AP30*12,AP30))))
B31: =AL31 | C31: =AM31 | D31: =AN31 | Y31: =IF(Z31<>"",1+Y30,"") | AB31: =IFERROR(VLOOKUP(Z31,'MIS FINANZAS'!$H$7:$J$103,3,0),"") | AC31: =IFERROR(VLOOKUP(Z31,'MIS FINANZAS'!$H$7:$L$103,5,0),"") | AD31: =IF(AB31="Bimensual",AC31/2,IF(AB31="Trimestral",AC31/3,IF(AB31="Semestral",AC31/6,IF(AB31="Anual",AC31/12,AC31)))) | AE31: =IF(AF31<>"",1+AE30,"") | AH31: =IFERROR(VLOOKUP(AF31,'MIS FINANZAS'!$H$7:$J$103,3,0),"") | AI31: =IFERROR(VLOOKUP(AF31,'MIS FINANZAS'!$H$7:$L$103,5,0),"") | AJ31: =IF(AH31="Bimensual",AI31/2,IF(AH31="Trimestral",AI31/3,IF(AH31="Semestral",AI31/6,IF(AH31="Anual",AI31/12,AI31)))) | AK31: 15 | AL31: =IFERROR(IFERROR(VLOOKUP(AK31,$Y:$AA,2,0),VLOOKUP(AK31,$AE:$AG,2,0)),"") | AM31: =IFERROR(IFERROR(VLOOKUP(AK31,$Y:$AA,3,0),VLOOKUP(AK31,$AE:$AG,3,0)),"") | AN31: =IFERROR(IFERROR(VLOOKUP(AK31,$Y:$AD,6,0),VLOOKUP(AK31,$AE:$AJ,6,0)),"") | AO31: =IFERROR(IFERROR(VLOOKUP(AK31,$Y:$AD,4,0),VLOOKUP(AK31,$AE:$AJ,4,0)),"") | AP31: =E31 | AQ31: =IF(AO31="Bimensual",AP31*2,IF(AO31="Trimestral",AP31*3,IF(AO31="Semestral",AP31*6,IF(AO31="Anual",AP31*12,AP31))))
B32: =AL32 | C32: =AM32 | D32: =AN32 | Y32: =IF(Z32<>"",1+Y31,"") | AB32: =IFERROR(VLOOKUP(Z32,'MIS FINANZAS'!$H$7:$J$103,3,0),"") | AC32: =IFERROR(VLOOKUP(Z32,'MIS FINANZAS'!$H$7:$L$103,5,0),"") | AD32: =IF(AB32="Bimensual",AC32/2,IF(AB32="Trimestral",AC32/3,IF(AB32="Semestral",AC32/6,IF(AB32="Anual",AC32/12,AC32)))) | AE32: =IF(AF32<>"",1+AE31,"") | AH32: =IFERROR(VLOOKUP(AF32,'MIS FINANZAS'!$H$7:$J$103,3,0),"") | AI32: =IFERROR(VLOOKUP(AF32,'MIS FINANZAS'!$H$7:$L$103,5,0),"") | AJ32: =IF(AH32="Bimensual",AI32/2,IF(AH32="Trimestral",AI32/3,IF(AH32="Semestral",AI32/6,IF(AH32="Anual",AI32/12,AI32)))) | AK32: 16 | AL32: =IFERROR(IFERROR(VLOOKUP(AK32,$Y:$AA,2,0),VLOOKUP(AK32,$AE:$AG,2,0)),"") | AM32: =IFERROR(IFERROR(VLOOKUP(AK32,$Y:$AA,3,0),VLOOKUP(AK32,$AE:$AG,3,0)),"") | AN32: =IFERROR(IFERROR(VLOOKUP(AK32,$Y:$AD,6,0),VLOOKUP(AK32,$AE:$AJ,6,0)),"") | AO32: =IFERROR(IFERROR(VLOOKUP(AK32,$Y:$AD,4,0),VLOOKUP(AK32,$AE:$AJ,4,0)),"") | AP32: =E32 | AQ32: =IF(AO32="Bimensual",AP32*2,IF(AO32="Trimestral",AP32*3,IF(AO32="Semestral",AP32*6,IF(AO32="Anual",AP32*12,AP32))))
B33: =AL33 | C33: =AM33 | D33: =AN33 | Y33: =IF(Z33<>"",1+Y32,"") | AB33: =IFERROR(VLOOKUP(Z33,'MIS FINANZAS'!$H$7:$J$103,3,0),"") | AC33: =IFERROR(VLOOKUP(Z33,'MIS FINANZAS'!$H$7:$L$103,5,0),"") | AD33: =IF(AB33="Bimensual",AC33/2,IF(AB33="Trimestral",AC33/3,IF(AB33="Semestral",AC33/6,IF(AB33="Anual",AC33/12,AC33)))) | AE33: =IF(AF33<>"",1+AE32,"") | AH33: =IFERROR(VLOOKUP(AF33,'MIS FINANZAS'!$H$7:$J$103,3,0),"") | AI33: =IFERROR(VLOOKUP(AF33,'MIS FINANZAS'!$H$7:$L$103,5,0),"") | AJ33: =IF(AH33="Bimensual",AI33/2,IF(AH33="Trimestral",AI33/3,IF(AH33="Semestral",AI33/6,IF(AH33="Anual",AI33/12,AI33)))) | AK33: 17 | AL33: =IFERROR(IFERROR(VLOOKUP(AK33,$Y:$AA,2,0),VLOOKUP(AK33,$AE:$AG,2,0)),"") | AM33: =IFERROR(IFERROR(VLOOKUP(AK33,$Y:$AA,3,0),VLOOKUP(AK33,$AE:$AG,3,0)),"") | AN33: =IFERROR(IFERROR(VLOOKUP(AK33,$Y:$AD,6,0),VLOOKUP(AK33,$AE:$AJ,6,0)),"") | AO33: =IFERROR(IFERROR(VLOOKUP(AK33,$Y:$AD,4,0),VLOOKUP(AK33,$AE:$AJ,4,0)),"") | AP33: =E33 | AQ33: =IF(AO33="Bimensual",AP33*2,IF(AO33="Trimestral",AP33*3,IF(AO33="Semestral",AP33*6,IF(AO33="Anual",AP33*12,AP33))))
B34: =AL34 | C34: =AM34 | D34: =AN34 | Y34: =IF(Z34<>"",1+Y33,"") | AB34: =IFERROR(VLOOKUP(Z34,'MIS FINANZAS'!$H$7:$J$103,3,0),"") | AC34: =IFERROR(VLOOKUP(Z34,'MIS FINANZAS'!$H$7:$L$103,5,0),"") | AD34: =IF(AB34="Bimensual",AC34/2,IF(AB34="Trimestral",AC34/3,IF(AB34="Semestral",AC34/6,IF(AB34="Anual",AC34/12,AC34)))) | AE34: =IF(AF34<>"",1+AE33,"") | AH34: =IFERROR(VLOOKUP(AF34,'MIS FINANZAS'!$H$7:$J$103,3,0),"") | AI34: =IFERROR(VLOOKUP(AF34,'MIS FINANZAS'!$H$7:$L$103,5,0),"") | AJ34: =IF(AH34="Bimensual",AI34/2,IF(AH34="Trimestral",AI34/3,IF(AH34="Semestral",AI34/6,IF(AH34="Anual",AI34/12,AI34)))) | AK34: 18 | AL34: =IFERROR(IFERROR(VLOOKUP(AK34,$Y:$AA,2,0),VLOOKUP(AK34,$AE:$AG,2,0)),"") | AM34: =IFERROR(IFERROR(VLOOKUP(AK34,$Y:$AA,3,0),VLOOKUP(AK34,$AE:$AG,3,0)),"") | AN34: =IFERROR(IFERROR(VLOOKUP(AK34,$Y:$AD,6,0),VLOOKUP(AK34,$AE:$AJ,6,0)),"") | AO34: =IFERROR(IFERROR(VLOOKUP(AK34,$Y:$AD,4,0),VLOOKUP(AK34,$AE:$AJ,4,0)),"") | AP34: =E34 | AQ34: =IF(AO34="Bimensual",AP34*2,IF(AO34="Trimestral",AP34*3,IF(AO34="Semestral",AP34*6,IF(AO34="Anual",AP34*12,AP34))))
B35: =AL35 | C35: =AM35 | D35: =AN35 | Y35: =IF(Z35<>"",1+Y34,"") | AB35: =IFERROR(VLOOKUP(Z35,'MIS FINANZAS'!$H$7:$J$103,3,0),"") | AC35: =IFERROR(VLOOKUP(Z35,'MIS FINANZAS'!$H$7:$L$103,5,0),"") | AD35: =IF(AB35="Bimensual",AC35/2,IF(AB35="Trimestral",AC35/3,IF(AB35="Semestral",AC35/6,IF(AB35="Anual",AC35/12,AC35)))) | AE35: =IF(AF35<>"",1+AE34,"") | AH35: =IFERROR(VLOOKUP(AF35,'MIS FINANZAS'!$H$7:$J$103,3,0),"") | AI35: =IFERROR(VLOOKUP(AF35,'MIS FINANZAS'!$H$7:$L$103,5,0),"") | AJ35: =IF(AH35="Bimensual",AI35/2,IF(AH35="Trimestral",AI35/3,IF(AH35="Semestral",AI35/6,IF(AH35="Anual",AI35/12,AI35)))) | AK35: 19 | AL35: =IFERROR(IFERROR(VLOOKUP(AK35,$Y:$AA,2,0),VLOOKUP(AK35,$AE:$AG,2,0)),"") | AM35: =IFERROR(IFERROR(VLOOKUP(AK35,$Y:$AA,3,0),VLOOKUP(AK35,$AE:$AG,3,0)),"") | AN35: =IFERROR(IFERROR(VLOOKUP(AK35,$Y:$AD,6,0),VLOOKUP(AK35,$AE:$AJ,6,0)),"") | AO35: =IFERROR(IFERROR(VLOOKUP(AK35,$Y:$AD,4,0),VLOOKUP(AK35,$AE:$AJ,4,0)),"") | AP35: =E35 | AQ35: =IF(AO35="Bimensual",AP35*2,IF(AO35="Trimestral",AP35*3,IF(AO35="Semestral",AP35*6,IF(AO35="Anual",AP35*12,AP35))))
B36: =AL36 | C36: =AM36 | D36: =AN36 | Y36: =IF(Z36<>"",1+Y35,"") | AB36: =IFERROR(VLOOKUP(Z36,'MIS FINANZAS'!$H$7:$J$103,3,0),"") | AC36: =IFERROR(VLOOKUP(Z36,'MIS FINANZAS'!$H$7:$L$103,5,0),"") | AD36: =IF(AB36="Bimensual",AC36/2,IF(AB36="Trimestral",AC36/3,IF(AB36="Semestral",AC36/6,IF(AB36="Anual",AC36/12,AC36)))) | AE36: =IF(AF36<>"",1+AE35,"") | AH36: =IFERROR(VLOOKUP(AF36,'MIS FINANZAS'!$H$7:$J$103,3,0),"") | AI36: =IFERROR(VLOOKUP(AF36,'MIS FINANZAS'!$H$7:$L$103,5,0),"") | AJ36: =IF(AH36="Bimensual",AI36/2,IF(AH36="Trimestral",AI36/3,IF(AH36="Semestral",AI36/6,IF(AH36="Anual",AI36/12,AI36)))) | AK36: 20 | AL36: =IFERROR(IFERROR(VLOOKUP(AK36,$Y:$AA,2,0),VLOOKUP(AK36,$AE:$AG,2,0)),"") | AM36: =IFERROR(IFERROR(VLOOKUP(AK36,$Y:$AA,3,0),VLOOKUP(AK36,$AE:$AG,3,0)),"") | AN36: =IFERROR(IFERROR(VLOOKUP(AK36,$Y:$AD,6,0),VLOOKUP(AK36,$AE:$AJ,6,0)),"") | AO36: =IFERROR(IFERROR(VLOOKUP(AK36,$Y:$AD,4,0),VLOOKUP(AK36,$AE:$AJ,4,0)),"") | AP36: =E36 | AQ36: =IF(AO36="Bimensual",AP36*2,IF(AO36="Trimestral",AP36*3,IF(AO36="Semestral",AP36*6,IF(AO36="Anual",AP36*12,AP36))))
B37: =AL37 | C37: =AM37 | D37: =AN37 | Y37: =IF(Z37<>"",1+Y36,"") | AB37: =IFERROR(VLOOKUP(Z37,'MIS FINANZAS'!$H$7:$J$103,3,0),"") | AC37: =IFERROR(VLOOKUP(Z37,'MIS FINANZAS'!$H$7:$L$103,5,0),"") | AD37: =IF(AB37="Bimensual",AC37/2,IF(AB37="Trimestral",AC37/3,IF(AB37="Semestral",AC37/6,IF(AB37="Anual",AC37/12,AC37)))) | AE37: =IF(AF37<>"",1+AE36,"") | AH37: =IFERROR(VLOOKUP(AF37,'MIS FINANZAS'!$H$7:$J$103,3,0),"") | AI37: =IFERROR(VLOOKUP(AF37,'MIS FINANZAS'!$H$7:$L$103,5,0),"") | AJ37: =IF(AH37="Bimensual",AI37/2,IF(AH37="Trimestral",AI37/3,IF(AH37="Semestral",AI37/6,IF(AH37="Anual",AI37/12,AI37)))) | AK37: 21 | AL37: =IFERROR(IFERROR(VLOOKUP(AK37,$Y:$AA,2,0),VLOOKUP(AK37,$AE:$AG,2,0)),"") | AM37: =IFERROR(IFERROR(VLOOKUP(AK37,$Y:$AA,3,0),VLOOKUP(AK37,$AE:$AG,3,0)),"") | AN37: =IFERROR(IFERROR(VLOOKUP(AK37,$Y:$AD,6,0),VLOOKUP(AK37,$AE:$AJ,6,0)),"") | AO37: =IFERROR(IFERROR(VLOOKUP(AK37,$Y:$AD,4,0),VLOOKUP(AK37,$AE:$AJ,4,0)),"") | AP37: =E37 | AQ37: =IF(AO37="Bimensual",AP37*2,IF(AO37="Trimestral",AP37*3,IF(AO37="Semestral",AP37*6,IF(AO37="Anual",AP37*12,AP37))))
B38: =AL38 | C38: =AM38 | D38: =AN38 | Y38: =IF(Z38<>"",1+Y37,"") | AB38: =IFERROR(VLOOKUP(Z38,'MIS FINANZAS'!$H$7:$J$103,3,0),"") | AC38: =IFERROR(VLOOKUP(Z38,'MIS FINANZAS'!$H$7:$L$103,5,0),"") | AD38: =IF(AB38="Bimensual",AC38/2,IF(AB38="Trimestral",AC38/3,IF(AB38="Semestral",AC38/6,IF(AB38="Anual",AC38/12,AC38)))) | AE38: =IF(AF38<>"",1+AE37,"") | AH38: =IFERROR(VLOOKUP(AF38,'MIS FINANZAS'!$H$7:$J$103,3,0),"") | AI38: =IFERROR(VLOOKUP(AF38,'MIS FINANZAS'!$H$7:$L$103,5,0),"") | AJ38: =IF(AH38="Bimensual",AI38/2,IF(AH38="Trimestral",AI38/3,IF(AH38="Semestral",AI38/6,IF(AH38="Anual",AI38/12,AI38)))) | AK38: 22 | AL38: =IFERROR(IFERROR(VLOOKUP(AK38,$Y:$AA,2,0),VLOOKUP(AK38,$AE:$AG,2,0)),"") | AM38: =IFERROR(IFERROR(VLOOKUP(AK38,$Y:$AA,3,0),VLOOKUP(AK38,$AE:$AG,3,0)),"") | AN38: =IFERROR(IFERROR(VLOOKUP(AK38,$Y:$AD,6,0),VLOOKUP(AK38,$AE:$AJ,6,0)),"") | AO38: =IFERROR(IFERROR(VLOOKUP(AK38,$Y:$AD,4,0),VLOOKUP(AK38,$AE:$AJ,4,0)),"") | AP38: =E38 | AQ38: =IF(AO38="Bimensual",AP38*2,IF(AO38="Trimestral",AP38*3,IF(AO38="Semestral",AP38*6,IF(AO38="Anual",AP38*12,AP38))))
B39: =AL39 | C39: =AM39 | D39: =AN39 | Y39: =IF(Z39<>"",1+Y38,"") | AB39: =IFERROR(VLOOKUP(Z39,'MIS FINANZAS'!$H$7:$J$103,3,0),"") | AC39: =IFERROR(VLOOKUP(Z39,'MIS FINANZAS'!$H$7:$L$103,5,0),"") | AD39: =IF(AB39="Bimensual",AC39/2,IF(AB39="Trimestral",AC39/3,IF(AB39="Semestral",AC39/6,IF(AB39="Anual",AC39/12,AC39)))) | AE39: =IF(AF39<>"",1+AE38,"") | AH39: =IFERROR(VLOOKUP(AF39,'MIS FINANZAS'!$H$7:$J$103,3,0),"") | AI39: =IFERROR(VLOOKUP(AF39,'MIS FINANZAS'!$H$7:$L$103,5,0),"") | AJ39: =IF(AH39="Bimensual",AI39/2,IF(AH39="Trimestral",AI39/3,IF(AH39="Semestral",AI39/6,IF(AH39="Anual",AI39/12,AI39)))) | AK39: 23 | AL39: =IFERROR(IFERROR(VLOOKUP(AK39,$Y:$AA,2,0),VLOOKUP(AK39,$AE:$AG,2,0)),"") | AM39: =IFERROR(IFERROR(VLOOKUP(AK39,$Y:$AA,3,0),VLOOKUP(AK39,$AE:$AG,3,0)),"") | AN39: =IFERROR(IFERROR(VLOOKUP(AK39,$Y:$AD,6,0),VLOOKUP(AK39,$AE:$AJ,6,0)),"") | AO39: =IFERROR(IFERROR(VLOOKUP(AK39,$Y:$AD,4,0),VLOOKUP(AK39,$AE:$AJ,4,0)),"") | AP39: =E39 | AQ39: =IF(AO39="Bimensual",AP39*2,IF(AO39="Trimestral",AP39*3,IF(AO39="Semestral",AP39*6,IF(AO39="Anual",AP39*12,AP39))))
B40: =AL40 | C40: =AM40 | D40: =AN40 | Y40: =IF(Z40<>"",1+Y39,"") | AB40: =IFERROR(VLOOKUP(Z40,'MIS FINANZAS'!$H$7:$J$103,3,0),"") | AC40: =IFERROR(VLOOKUP(Z40,'MIS FINANZAS'!$H$7:$L$103,5,0),"") | AD40: =IF(AB40="Bimensual",AC40/2,IF(AB40="Trimestral",AC40/3,IF(AB40="Semestral",AC40/6,IF(AB40="Anual",AC40/12,AC40)))) | AE40: =IF(AF40<>"",1+AE39,"") | AH40: =IFERROR(VLOOKUP(AF40,'MIS FINANZAS'!$H$7:$J$103,3,0),"") | AI40: =IFERROR(VLOOKUP(AF40,'MIS FINANZAS'!$H$7:$L$103,5,0),"") | AJ40: =IF(AH40="Bimensual",AI40/2,IF(AH40="Trimestral",AI40/3,IF(AH40="Semestral",AI40/6,IF(AH40="Anual",AI40/12,AI40)))) | AK40: 24 | AL40: =IFERROR(IFERROR(VLOOKUP(AK40,$Y:$AA,2,0),VLOOKUP(AK40,$AE:$AG,2,0)),"") | AM40: =IFERROR(IFERROR(VLOOKUP(AK40,$Y:$AA,3,0),VLOOKUP(AK40,$AE:$AG,3,0)),"") | AN40: =IFERROR(IFERROR(VLOOKUP(AK40,$Y:$AD,6,0),VLOOKUP(AK40,$AE:$AJ,6,0)),"") | AO40: =IFERROR(IFERROR(VLOOKUP(AK40,$Y:$AD,4,0),VLOOKUP(AK40,$AE:$AJ,4,0)),"") | AP40: =E40 | AQ40: =IF(AO40="Bimensual",AP40*2,IF(AO40="Trimestral",AP40*3,IF(AO40="Semestral",AP40*6,IF(AO40="Anual",AP40*12,AP40))))
... B118: =AL118 | C118: =AM118 | D118: =AN118 | Y118: =IF(Z118<>"",1+Y117,"") | AB118: =IFERROR(VLOOKUP(Z118,'MIS FINANZAS'!$H$7:$J$103,3,0),"") | AC118: =IFERROR(VLOOKUP(Z118,'MIS FINANZAS'!$H$7:$L$103,5,0),"") | AD118: =IF(AB118="Bimensual",AC118/2,IF(AB118="Trimestral",AC118/3,IF(AB118="Semestral",AC118/6,IF(AB118="Anual",AC118/12,AC118)))) | AE118: =IF(AF118<>"",1+AE117,"") | AH118: =IFERROR(VLOOKUP(AF118,'MIS FINANZAS'!$H$7:$J$103,3,0),"") | AI118: =IFERROR(VLOOKUP(AF118,'MIS FINANZAS'!$H$7:$L$103,5,0),"") | AJ118: =IF(AH118="Bimensual",AI118/2,IF(AH118="Trimestral",AI118/3,IF(AH118="Semestral",AI118/6,IF(AH118="Anual",AI118/12,AI118)))) | AK118: 102 | AL118: =IFERROR(IFERROR(VLOOKUP(AK118,$Y:$AA,2,0),VLOOKUP(AK118,$AE:$AG,2,0)),"") | AM118: =IFERROR(IFERROR(VLOOKUP(AK118,$Y:$AA,3,0),VLOOKUP(AK118,$AE:$AG,3,0)),"") | AN118: =IFERROR(IFERROR(VLOOKUP(AK118,$Y:$AD,6,0),VLOOKUP(AK118,$AE:$AJ,6,0)),"") | AO118: =IFERROR(IFERROR(VLOOKUP(AK118,$Y:$AD,4,0),VLOOKUP(AK118,$AE:$AJ,4,0)),"") | AP118: =E118 | AQ118: =IF(AO118="Bimensual",AP118*2,IF(AO118="Trimestral",AP118*3,IF(AO118="Semestral",AP118*6,IF(AO118="Anual",AP118*12,AP118))))

Sheet ESTADO DE RESULTADOS
B2: ESTADO DE RESULTADOS INICIAL | F2: ESTADO DE RESULTADOS MEJORADO
B4: (+) | C4: INGRESOS MENSUALES | D4: =D5+D6 -> 7200000 | F4: (+) | G4: INGRESOS MENSUALES | H4: =H5+H6 -> 7200000
C5: Ingresos fijos | D5: =PRESUPUESTO!C12 -> 4333333.3 | G5: Ingresos fijos | H5: =SUMIF('PRESUPUESTO MEJORADO'!D:D,"Fijo",'PRESUPUESTO MEJORADO'!H:H) -> 4333333.3
C6: Ingresos variables | D6: =PRESUPUESTO!D12 -> 2866666.7 | G6: Ingresos variables | H6: =SUMIF('PRESUPUESTO MEJORADO'!D:D,"Variable",'PRESUPUESTO MEJORADO'!H:H) -> 2866666.7
B7: (-) | C7: GASTOS FIJOS | D7: =D8+D9 -> 3860000 | F7: (-) | G7: GASTOS FIJOS | H7: =H8+H9 -> 3860000
C8: Gastos fijos necesarios | D8: =PRESUPUESTO!C24-PRESUPUESTO!F19-PRESUPUESTO!F18-PRESUPUESTO!F17 -> 3660000 | G8: Gastos fijos necesarios | H8: =PRESUPUESTO!C24-PRESUPUESTO!F19-PRESUPUESTO!F18-PRESUPUESTO!F17 -> 3660000
C9: Gastos fijos provisiones | D9: =PRESUPUESTO!F17 -> 200000 | G9: Gastos fijos provisiones | H9: =PRESUPUESTO!F17 -> 200000
B10: (-) | C10: DEUDAS | D10: =D11+D12 -> 1200000 | F10: (-) | G10: DEUDAS | H10: =H11+H12 -> 1200000
C11: Cuota deudas entidades | D11: =PRESUPUESTO!F18 -> 1200000 | G11: Cuota deudas entidades | H11: =PRESUPUESTO!F18 -> 1200000
C12: Cuota deudas conocidos | D12: =PRESUPUESTO!F19 -> 0 | G12: Cuota deudas conocidos | H12: =PRESUPUESTO!F19 -> 0
B14: (=) | C14: FLUJO DE AHORRO 1 | D14: =D4-D7-D10 -> 2140000 | F14: (=) | G14: FLUJO DE AHORRO 1 | H14: =H4-H7-H10 -> 2140000
B16: (-) | C16: SALARIO PERSONAL | F16: (-) | G16: SALARIO PERSONAL | H16: ='MIS FINANZAS'!C3 -> 500000
B17: (-) | C17: GASTOS VARIABLES | D17: =D18+D19 -> 3285000 | F17: (-) | G17: GASTOS VARIABLES | H17: =H18+H19 -> 1215000
C18: Gastos no tan necesarios | D18: =PRESUPUESTO!D24 -> 1665000 | G18: Gastos no tan necesarios | H18: =SUMIF('PRESUPUESTO MEJORADO'!D:D,"No tan necesario",'PRESUPUESTO MEJORADO'!H:H) -> 715000
